Workbook
Name Burn: [1]Projections!$E$63
Name Conversion1: [1]Projections!$D$18
Name Conversion2: [1]Projections!$D$19
Name Conversion3: [1]Projections!$D$20
Name CostPerUser: [1]Projections!$D$55
Name Price1: [1]Projections!$D$25
Name Price2: [1]Projections!$D$26
Name Price3: [1]Projections!$D$27
Name PricePSF: [1]Projections!$D$54
Name SFpp: [1]Projections!$D$53

Sheet ChargeHelp Example
A1: ChargerHelp, Inc.
A2: Profit and Loss
A3: January - June, 2023
B5: Jan 2023 | C5: Feb 2023 | D5: Mar 2023 | E5: Apr 2023 | F5: May 2023 | G5: Jun 2023 | H5: Total
A6: Income
A7: 40000 Technician Maintenance & Repairs Income | B7: =54256.58 -> 54256.58 | C7: =31504.6 -> 31504.6 | D7: =29168.4 -> 29168.4 | E7: =85981.73 -> 85981.73 | F7: =79117.05 -> 79117.05 | G7: =107813.22 -> 107813.22 | H7: =(((((B7)+(C7))+(D7))+(E7))+(F7))+(G7) -> 387841.58
A8: 40100 Campaigns | B8: =37145 -> 37145 | C8: =16910 -> 16910 | D8: =18905 -> 18905 | E8: =10355 -> 10355 | H8: =(((((B8)+(C8))+(D8))+(E8))+(F8))+(G8) -> 83315
A9: Total 40000 Technician Maintenance & Repairs Income | B9: =(B7)+(B8) -> 91401.58 | C9: =(C7)+(C8) -> 48414.6 | D9: =(D7)+(D8) -> 48073.4 | E9: =(E7)+(E8) -> 96336.73 | F9: =(F7)+(F8) -> 79117.05 | G9: =(G7)+(G8) -> 107813.22 | H9: =(((((B9)+(C9))+(D9))+(E9))+(F9))+(G9) -> 471156.58
A10: 44000 Workforce Development & Training Income | B10: =25000 -> 25000 | C10: =50000 -> 50000 | D10: =75000 -> 75000 | E10: =74000 -> 74000 | F10: =25000 -> 25000 | G10: =100000 -> 100000 | H10: =(((((B10)+(C10))+(D10))+(E10))+(F10))+(G10) -> 349000
A11: 45000 Reliability as a Service (RaaS) Income | B11: =37990 -> 37990 | C11: =39830 -> 39830 | D11: =40430 -> 40430 | E11: =40430 -> 40430 | F11: =42870 -> 42870 | G11: =42870 -> 42870 | H11: =(((((B11)+(C11))+(D11))+(E11))+(F11))+(G11) -> 244420
A12: 46000 Warranty Revenue | F12: =0 -> 0 | H12: =(((((B12)+(C12))+(D12))+(E12))+(F12))+(G12) -> 0
A13: Total Income | B13: =(((B9)+(B10))+(B11))+(B12) -> 154391.58 | C13: =(((C9)+(C10))+(C11))+(C12) -> 138244.6 | D13: =(((D9)+(D10))+(D11))+(D12) -> 163503.4 | E13: =(((E9)+(E10))+(E11))+(E12) -> 210766.73 | F13: =(((F9)+(F10))+(F11))+(F12) -> 146987.05 | G13: =(((G9)+(G10))+(G11))+(G12) -> 250683.22 | H13: =(((((B13)+(C13))+(D13))+(E13))+(F13))+(G13) -> 1064576.6
A14: Cost of Goods Sold
A15: 50000 Technician Costs | B15: =B16/B25 -> 0.66346111 | C15: =C16/C25 -> 0.67351763 | D15: =D16/D25 -> 0.67354879 | E15: =E16/E25 -> 0.59599531 | F15: =F16/F25 -> 0.61282405 | G15: =G16/G25 -> 0.6872657 | H15: =H16/H25 -> 0.65265665
A16: 50010 Technician Salaries | B16: =74743.01 -> 74743.01 | C16: =69057.57 -> 69057.57 | D16: =86660.73 -> 86660.73 | E16: =66940.2 -> 66940.2 | F16: =70956.27 -> 70956.27 | G16: =97937.34 -> 97937.34 | H16: =(((((B16)+(C16))+(D16))+(E16))+(F16))+(G16) -> 466295.12
A17: 50020 Technician Taxes | B17: =8584.26 -> 8584.26 | C17: =5466.83 -> 5466.83 | D17: =6757.23 -> 6757.23 | E17: =5796.89 -> 5796.89 | F17: =6167.03 -> 6167.03 | G17: =8370.66 -> 8370.66 | H17: =(((((B17)+(C17))+(D17))+(E17))+(F17))+(G17) -> 41142.9
A18: 50030 Technician Benefits | B18: =9749.53 -> 9749.53 | C18: =8550 -> 8550 | D18: =10607.64 -> 10607.64 | E18: =11505.71 -> 11505.71 | F18: =14358.17 -> 14358.17 | G18: =14811.2 -> 14811.2 | H18: =(((((B18)+(C18))+(D18))+(E18))+(F18))+(G18) -> 69582.25
A19: 50040 Technician Tool Costs | B19: =7189.3 -> 7189.3 | C19: =12614.87 -> 12614.87 | D19: =6631.86 -> 6631.86 | E19: =16116.88 -> 16116.88 | F19: =10941.52 -> 10941.52 | G19: =8303.1 -> 8303.1 | H19: =(((((B19)+(C19))+(D19))+(E19))+(F19))+(G19) -> 61797.53
A20: 50050 Technician Parking Charges | B20: =10 -> 10 | C20: =40.86 -> 40.86 | H20: =(((((B20)+(C20))+(D20))+(E20))+(F20))+(G20) -> 50.86
A21: 50060 Technician Toll Fees | B21: =425 -> 425 | C21: =291.57 -> 291.57 | D21: =830.15 -> 830.15 | E21: =435 -> 435 | F21: =345.53 -> 345.53 | G21: =481.2 -> 481.2 | H21: =(((((B21)+(C21))+(D21))+(E21))+(F21))+(G21) -> 2808.45
A22: 50070 Technician - Travel Expense | B22: =11754.44 -> 11754.44 | C22: =6510.31 -> 6510.31 | D22: =10156.21 -> 10156.21 | E22: =9853.05 -> 9853.05 | F22: =8831.58 -> 8831.58 | G22: =9507.07 -> 9507.07 | H22: =(((((B22)+(C22))+(D22))+(E22))+(F22))+(G22) -> 56612.66
A23: 50085 Technician EV costs | D23: =7018.39 -> 7018.39 | E23: =1668.33 -> 1668.33 | F23: =4185 -> 4185 | G23: =3091.62 -> 3091.62 | H23: =(((((B23)+(C23))+(D23))+(E23))+(F23))+(G23) -> 15963.34
A24: 50095 Technician - Per Diem | B24: =200 -> 200 | H24: =(((((B24)+(C24))+(D24))+(E24))+(F24))+(G24) -> 200
A25: Total 50000 Technician Costs | B25: =(((((((((B15)+(B16))+(B17))+(B18))+(B19))+(B20))+(B21))+(B22))+(B23))+(B24) -> 112656.2 | C25: =(((((((((C15)+(C16))+(C17))+(C18))+(C19))+(C20))+(C21))+(C22))+(C23))+(C24) -> 102532.68 | D25: =(((((((((D15)+(D16))+(D17))+(D18))+(D19))+(D20))+(D21))+(D22))+(D23))+(D24) -> 128662.88 | E25: =(((((((((E15)+(E16))+(E17))+(E18))+(E19))+(E20))+(E21))+(E22))+(E23))+(E24) -> 112316.66 | F25: =(((((((((F15)+(F16))+(F17))+(F18))+(F19))+(F20))+(F21))+(F22))+(F23))+(F24) -> 115785.71 | G25: =(((((((((G15)+(G16))+(G17))+(G18))+(G19))+(G20))+(G21))+(G22))+(G23))+(G24) -> 142502.88 | H25: =(((((B25)+(C25))+(D25))+(E25))+(F25))+(G25) -> 714457.02
A26: 53000 Contractor Costs | C26: =2278.5 -> 2278.5 | D26: =5628.58 -> 5628.58 | H26: =(((((B26)+(C26))+(D26))+(E26))+(F26))+(G26) -> 7907.08
A27: 53200 Contractor Costs | B27: =43783.5 -> 43783.5 | C27: =39756.96 -> 39756.96 | D27: =54377.18 -> 54377.18 | E27: =66233.27 -> 66233.27 | F27: =66098.32 -> 66098.32 | G27: =60538.27 -> 60538.27 | H27: =(((((B27)+(C27))+(D27))+(E27))+(F27))+(G27) -> 330787.5
A28: Total 53000 Contractor Costs | B28: =(B26)+(B27) -> 43783.5 | C28: =(C26)+(C27) -> 42035.46 | D28: =(D26)+(D27) -> 60005.76 | E28: =(E26)+(E27) -> 66233.27 | F28: =(F26)+(F27) -> 66098.32 | G28: =(G26)+(G27) -> 60538.27 | H28: =(((((B28)+(C28))+(D28))+(E28))+(F28))+(G28) -> 338694.58
A29: 55000 Workforce Development Training Costs | H29: =(((((B29)+(C29))+(D29))+(E29))+(F29))+(G29) -> 0
A30: 55100 Training Personnel | B30: =6000 -> 6000 | C30: =6000 -> 6000 | D30: =9000 -> 9000 | E30: =11100 -> 11100 | F30: =6000 -> 6000 | G30: =13724.51 -> 13724.51 | H30: =(((((B30)+(C30))+(D30))+(E30))+(F30))+(G30) -> 51824.51
A31: 55120 Training Personnel Taxes | B31: =831.31 -> 831.31 | C31: =512.99 -> 512.99 | D31: =659.8 -> 659.8 | E31: =616.01 -> 616.01 | F31: =616.03 -> 616.03 | G31: =484.04 -> 484.04 | H31: =(((((B31)+(C31))+(D31))+(E31))+(F31))+(G31) -> 3720.18
A32: 55130 Training Personnel Benefits | B32: =566.64 -> 566.64 | C32: =1067.8 -> 1067.8 | D32: =1601.7 -> 1601.7 | E32: =1536.33 -> 1536.33 | F32: =1547.67 -> 1547.67 | G32: =1216.03 -> 1216.03 | H32: =(((((B32)+(C32))+(D32))+(E32))+(F32))+(G32) -> 7536.17
A33: 55200 Other Training Costs | B33: =1500 -> 1500 | C33: =3000 -> 3000 | D33: =3000 -> 3000 | H33: =(((((B33)+(C33))+(D33))+(E33))+(F33))+(G33) -> 7500
A34: Total 55000 Workforce Development Training Costs | B34: =((((B29)+(B30))+(B31))+(B32))+(B33) -> 8897.95 | C34: =((((C29)+(C30))+(C31))+(C32))+(C33) -> 10580.79 | D34: =((((D29)+(D30))+(D31))+(D32))+(D33) -> 14261.5 | E34: =((((E29)+(E30))+(E31))+(E32))+(E33) -> 13252.34 | F34: =((((F29)+(F30))+(F31))+(F32))+(F33) -> 8163.7 | G34: =((((G29)+(G30))+(G31))+(G32))+(G33) -> 15424.58 | H34: =(((((B34)+(C34))+(D34))+(E34))+(F34))+(G34) -> 70580.86
A35: Inventory Shrinkage | G35: =0 -> 0 | H35: =(((((B35)+(C35))+(D35))+(E35))+(F35))+(G35) -> 0
A36: Total Cost of Goods Sold | B36: =(((B25)+(B28))+(B34))+(B35) -> 165337.65 | C36: =(((C25)+(C28))+(C34))+(C35) -> 155148.93 | D36: =(((D25)+(D28))+(D34))+(D35) -> 202930.14 | E36: =(((E25)+(E28))+(E34))+(E35) -> 191802.27 | F36: =(((F25)+(F28))+(F34))+(F35) -> 190047.73 | G36: =(((G25)+(G28))+(G34))+(G35) -> 218465.73 | H36: =(((((B36)+(C36))+(D36))+(E36))+(F36))+(G36) -> 1123732.5
A37: Gross Profit | B37: =(B13)-(B36) -> -10946.073 | C37: =(C13)-(C36) -> -16904.334 | D37: =(D13)-(D36) -> -39426.744 | E37: =(E13)-(E36) -> 18964.464 | F37: =(F13)-(F36) -> -43060.683 | G37: =(G13)-(G36) -> 32217.493 | H37: =(((((B37)+(C37))+(D37))+(E37))+(F37))+(G37) -> -59155.877
A38: Expenses
A39: 60100 Personnel Costs | H39: =(((((B39)+(C39))+(D39))+(E39))+(F39))+(G39) -> 0
A40: 60110 Salaries & Wages | B40: =105551.35 -> 105551.35 | C40: =95144.78 -> 95144.78 | D40: =122680.5 -> 122680.5 | E40: =123679.89 -> 123679.89 | F40: =180764.76 -> 180764.76 | G40: =252938.89 -> 252938.89 | H40: =(((((B40)+(C40))+(D40))+(E40))+(F40))+(G40) -> 880760.17
A41: 60120 Payroll Taxes | B41: =10268.21 -> 10268.21 | C41: =7172.29 -> 7172.29 | D41: =9854.82 -> 9854.82 | E41: =9706.51 -> 9706.51 | F41: =15858.82 -> 15858.82 | G41: =20704.99 -> 20704.99 | H41: =(((((B41)+(C41))+(D41))+(E41))+(F41))+(G41) -> 73565.64
...

Sheet Price
B2: Rev | C2: Single Product
D3: Requires Tech Team
D4: Subscription Service
D5: Churn
B8: Cost
C9: Salaries | D9: VC
C10: Battery Degredation | D10: VC | E10: Batteries degarde 1.8% per yer
C12: Production | D12: VC
C13: Logistics
C14: Recycling the battery

Sheet Aid
B3: Users | C3: 1000000 | D3: people
G4: Sunrun Inc.
B5: Activation | C5: 0.85 | D5: Using | G5: Tesla, Inc.
G6: Samsara Inc.
B7: Total Activated | C7: =C3*C5 -> 850000 | G7: ChargePoint Holdings, Inc.
G8: ServiceTitan, Inc.
B9: Subscription Conversion | C9: 0.02 | G9: Nextracker Inc.
G10: Karooooo Ltd.
B11: Number of Free Users | C11: =(1-C9)*C7 -> 833000 | G11: Siemens Aktiengesellschaft
B12: Number of Subscribers | C12: =C9*C7 -> 17000
B14: Subscription Fee | C14: 19
B16: Total | C16: =C14*C12 -> 323000
B19: -You offer a subscription service that includes upgrades or replacements | C19: COST item

Sheet RevnueDrivers>>

Sheet Head Count
F1: Yr | H1: 1 | I1: =H1+1 -> 2 | J1: =I1+1 -> 3 | K1: =J1+1 -> 4 | L1: =K1+1 -> 5 | M1: =L1+1 -> 6 | N1: =M1+1 -> 7 | O1: =N1+1 -> 8 | P1: =O1+1 -> 9 | ... V1: =U1+1 -> 15
A3: Head Count | B3: Starting Value | C3: Starting Year | D3: Increment Value | E3: Every X Years | F3: Max Value
A4: Technicians | B4: 1 | C4: 1 | D4: 1 | E4: 3 | F4: 6 | H4: =MIN($F$4,IF(H$1<$C$4,0,IF(H$1=$C4,$B4,IF(IF($D4>0,MOD(H$1-$C$4,$E4)=0,0),G4+$D4,G4)))) -> 1 | I4: =MIN($F$4,IF(I$1<$C$4,0,IF(I$1=$C4,$B4,IF(IF($D4>0,MOD(I$1-$C$4,$E4)=0,0),H4+$D4,H4)))) -> 1 | J4: =MIN($F$4,IF(J$1<$C$4,0,IF(J$1=$C4,$B4,IF(IF($D4>0,MOD(J$1-$C$4,$E4)=0,0),I4+$D4,I4)))) -> 1 | K4: =MIN($F$4,IF(K$1<$C$4,0,IF(K$1=$C4,$B4,IF(IF($D4>0,MOD(K$1-$C$4,$E4)=0,0),J4+$D4,J4)))) -> 2 | L4: =MIN($F$4,IF(L$1<$C$4,0,IF(L$1=$C4,$B4,IF(IF($D4>0,MOD(L$1-$C$4,$E4)=0,0),K4+$D4,K4)))) -> 2 | M4: =MIN($F$4,IF(M$1<$C$4,0,IF(M$1=$C4,$B4,IF(IF($D4>0,MOD(M$1-$C$4,$E4)=0,0),L4+$D4,L4)))) -> 2 | N4: =MIN($F$4,IF(N$1<$C$4,0,IF(N$1=$C4,$B4,IF(IF($D4>0,MOD(N$1-$C$4,$E4)=0,0),M4+$D4,M4)))) -> 3 | O4: =MIN($F$4,IF(O$1<$C$4,0,IF(O$1=$C4,$B4,IF(IF($D4>0,MOD(O$1-$C$4,$E4)=0,0),N4+$D4,N4)))) -> 3 | ... V4: =MIN($F$4,IF(V$1<$C$4,0,IF(V$1=$C4,$B4,IF(IF($D4>0,MOD(V$1-$C$4,$E4)=0,0),U4+$D4,U4)))) -> 5
A7: Avg All in Compensation | B7: Starting Value | C7: Starting Year | D7: Increment Value | E7: Every X Years | F7: Max Per Year/Head Count
A8: Technicians | B8: 60000 | C8: =C4 -> 1 | D8: 10000 | E8: 2 | F8: 92000 | H8: =IF(H$1=$C8,$B8,IF(IF($D8>0,MOD(H$1,$E8)=0,0),MIN($F8,G8+$D8),G8)) -> 60000 | I8: =IF(I$1=$C8,$B8,IF(IF($D8>0,MOD(I$1,$E8)=0,0),MIN($F8,H8+$D8),H8)) -> 70000 | J8: =IF(J$1=$C8,$B8,IF(IF($D8>0,MOD(J$1,$E8)=0,0),MIN($F8,I8+$D8),I8)) -> 70000 | K8: =IF(K$1=$C8,$B8,IF(IF($D8>0,MOD(K$1,$E8)=0,0),MIN($F8,J8+$D8),J8)) -> 80000 | L8: =IF(L$1=$C8,$B8,IF(IF($D8>0,MOD(L$1,$E8)=0,0),MIN($F8,K8+$D8),K8)) -> 80000 | M8: =IF(M$1=$C8,$B8,IF(IF($D8>0,MOD(M$1,$E8)=0,0),MIN($F8,L8+$D8),L8)) -> 90000 | N8: =IF(N$1=$C8,$B8,IF(IF($D8>0,MOD(N$1,$E8)=0,0),MIN($F8,M8+$D8),M8)) -> 90000 | O8: =IF(O$1=$C8,$B8,IF(IF($D8>0,MOD(O$1,$E8)=0,0),MIN($F8,N8+$D8),N8)) -> 92000 | ... V8: =IF(V$1=$C8,$B8,IF(IF($D8>0,MOD(V$1,$E8)=0,0),MIN($F8,U8+$D8),U8)) -> 92000
F11: Total Compensation
F12: Technicians | H12: =H4*H8 -> 60000 | I12: =I4*I8 -> 70000 | J12: =J4*J8 -> 70000 | K12: =K4*K8 -> 160000 | L12: =L4*L8 -> 160000 | M12: =M4*M8 -> 180000 | N12: =N4*N8 -> 270000 | O12: =O4*O8 -> 276000 | ... V12: =V4*V8 -> 460000

Sheet GrowthForecast
Q27: How can we model growth?
Q37: This should cover intrest in new tech

Sheet ChurnMatrix
D4: Month | E4: ='P&Lv2'!D5 -> 1 | F4: =E4+1 -> 2 | G4: =F4+1 -> 3 | H4: =G4+1 -> 4 | I4: =H4+1 -> 5 | J4: =I4+1 -> 6
D5: User Retention | E5: 0.56 | F5: 0.25 | G5: 0.25 | H5: 0.23 | I5: 0.11 | J5: 0.11
C9: Yr | D9: 1 | E9: =D9+1 -> 2 | F9: =E9+1 -> 3 | G9: =F9+1 -> 4 | H9: =G9+1 -> 5 | I9: =H9+1 -> 6 | J9: =I9+1 -> 7 | K9: =J9+1 -> 8 | L9: =K9+1 -> 9 | M9: =L9+1 -> 10
B11: Inputs Rev | C11: New customers | D11: ='P&Lv2'!D15 -> 1300 | E11: ='P&Lv2'!E15 -> 2000 | F11: ='P&Lv2'!F15 -> 3300 | G11: ='P&Lv2'!G15 -> 3465 | H11: ='P&Lv2'!H15 -> 3638.25 | I11: ='P&Lv2'!I15 -> 3820.1625 | J11: ='P&Lv2'!J15 -> 4011.1706 | K11: ='P&Lv2'!K15 -> 4211.7292 | ... M11: ='P&Lv2'!M15 -> 4643.4314
C13: Total Customers | D13: =D11 -> 1300 | E13: =(E11+D13) +E98 -> 2897 | F13: =(F11+E13) +F98 -> 5577 | G13: =(G11+F13) +G98 -> 7993 | H13: =(H11+G13) +H98 -> 10361.1 | I13: =(I11+H13) +I98 -> 12747.405 | J13: =(J11+I13) +J98 -> 15109.025 | K13: =(K11+J13) +K98 -> 17588.727 | L13: =(L11+K13) +L98 -> 20192.413 | M13: =(M11+L13) +M98 -> 22926.283
C15: Cohort Retention
C16: 1 | D16: =ChurnMatrix!E$5 -> 0.56 | E16: =ChurnMatrix!F$5 -> 0.25 | F16: =ChurnMatrix!G$5 -> 0.25 | G16: =ChurnMatrix!H$5 -> 0.23 | H16: =ChurnMatrix!I$5 -> 0.11 | I16: =ChurnMatrix!J$5 -> 0.11
C17: =C16+1 -> 2 | D17: =IF(OR(D$9>($C17+5),(D$9-$C17)<0),"",_xlfn.XLOOKUP(D$9-$C16,ChurnMatrix!$E$4:$J$4,ChurnMatrix!$E$5:$J$5)) | E17: =IF(OR(E$9>($C17+5),(E$9-$C17)<0),"",_xlfn.XLOOKUP(E$9-$C16,ChurnMatrix!$E$4:$J$4,ChurnMatrix!$E$5:$J$5)) -> 0.56 | F17: =IF(OR(F$9>($C17+5),(F$9-$C17)<0),"",_xlfn.XLOOKUP(F$9-$C16,ChurnMatrix!$E$4:$J$4,ChurnMatrix!$E$5:$J$5)) -> 0.25 | G17: =IF(OR(G$9>($C17+5),(G$9-$C17)<0),"",_xlfn.XLOOKUP(G$9-$C16,ChurnMatrix!$E$4:$J$4,ChurnMatrix!$E$5:$J$5)) -> 0.25 | H17: =IF(OR(H$9>($C17+5),(H$9-$C17)<0),"",_xlfn.XLOOKUP(H$9-$C16,ChurnMatrix!$E$4:$J$4,ChurnMatrix!$E$5:$J$5)) -> 0.23 | I17: =IF(OR(I$9>($C17+5),(I$9-$C17)<0),"",_xlfn.XLOOKUP(I$9-$C16,ChurnMatrix!$E$4:$J$4,ChurnMatrix!$E$5:$J$5)) -> 0.11 | J17: =IF(OR(J$9>($C17+5),(J$9-$C17)<0),"",_xlfn.XLOOKUP(J$9-$C16,ChurnMatrix!$E$4:$J$4,ChurnMatrix!$E$5:$J$5)) -> 0.11 | K17: =IF(OR(K$9>($C17+5),(K$9-$C17)<0),"",_xlfn.XLOOKUP(K$9-$C16,ChurnMatrix!$E$4:$J$4,ChurnMatrix!$E$5:$J$5)) | ... M17: =IF(OR(M$9>($C17+5),(M$9-$C17)<0),"",_xlfn.XLOOKUP(M$9-$C16,ChurnMatrix!$E$4:$J$4,ChurnMatrix!$E$5:$J$5))
C18: =C17+1 -> 3 | D18: =IF(OR(D$9>($C18+5),(D$9-$C18)<0),"",_xlfn.XLOOKUP(D$9-$C17,ChurnMatrix!$E$4:$J$4,ChurnMatrix!$E$5:$J$5)) | E18: =IF(OR(E$9>($C18+5),(E$9-$C18)<0),"",_xlfn.XLOOKUP(E$9-$C17,ChurnMatrix!$E$4:$J$4,ChurnMatrix!$E$5:$J$5)) | F18: =IF(OR(F$9>($C18+5),(F$9-$C18)<0),"",_xlfn.XLOOKUP(F$9-$C17,ChurnMatrix!$E$4:$J$4,ChurnMatrix!$E$5:$J$5)) -> 0.56 | G18: =IF(OR(G$9>($C18+5),(G$9-$C18)<0),"",_xlfn.XLOOKUP(G$9-$C17,ChurnMatrix!$E$4:$J$4,ChurnMatrix!$E$5:$J$5)) -> 0.25 | H18: =IF(OR(H$9>($C18+5),(H$9-$C18)<0),"",_xlfn.XLOOKUP(H$9-$C17,ChurnMatrix!$E$4:$J$4,ChurnMatrix!$E$5:$J$5)) -> 0.25 | I18: =IF(OR(I$9>($C18+5),(I$9-$C18)<0),"",_xlfn.XLOOKUP(I$9-$C17,ChurnMatrix!$E$4:$J$4,ChurnMatrix!$E$5:$J$5)) -> 0.23 | J18: =IF(OR(J$9>($C18+5),(J$9-$C18)<0),"",_xlfn.XLOOKUP(J$9-$C17,ChurnMatrix!$E$4:$J$4,ChurnMatrix!$E$5:$J$5)) -> 0.11 | K18: =IF(OR(K$9>($C18+5),(K$9-$C18)<0),"",_xlfn.XLOOKUP(K$9-$C17,ChurnMatrix!$E$4:$J$4,ChurnMatrix!$E$5:$J$5)) -> 0.11 | ... M18: =IF(OR(M$9>($C18+5),(M$9-$C18)<0),"",_xlfn.XLOOKUP(M$9-$C17,ChurnMatrix!$E$4:$J$4,ChurnMatrix!$E$5:$J$5))
C19: =C18+1 -> 4 | D19: =IF(OR(D$9>($C19+5),(D$9-$C19)<0),"",_xlfn.XLOOKUP(D$9-$C18,ChurnMatrix!$E$4:$J$4,ChurnMatrix!$E$5:$J$5)) | E19: =IF(OR(E$9>($C19+5),(E$9-$C19)<0),"",_xlfn.XLOOKUP(E$9-$C18,ChurnMatrix!$E$4:$J$4,ChurnMatrix!$E$5:$J$5)) | F19: =IF(OR(F$9>($C19+5),(F$9-$C19)<0),"",_xlfn.XLOOKUP(F$9-$C18,ChurnMatrix!$E$4:$J$4,ChurnMatrix!$E$5:$J$5)) | G19: =IF(OR(G$9>($C19+5),(G$9-$C19)<0),"",_xlfn.XLOOKUP(G$9-$C18,ChurnMatrix!$E$4:$J$4,ChurnMatrix!$E$5:$J$5)) -> 0.56 | H19: =IF(OR(H$9>($C19+5),(H$9-$C19)<0),"",_xlfn.XLOOKUP(H$9-$C18,ChurnMatrix!$E$4:$J$4,ChurnMatrix!$E$5:$J$5)) -> 0.25 | I19: =IF(OR(I$9>($C19+5),(I$9-$C19)<0),"",_xlfn.XLOOKUP(I$9-$C18,ChurnMatrix!$E$4:$J$4,ChurnMatrix!$E$5:$J$5)) -> 0.25 | J19: =IF(OR(J$9>($C19+5),(J$9-$C19)<0),"",_xlfn.XLOOKUP(J$9-$C18,ChurnMatrix!$E$4:$J$4,ChurnMatrix!$E$5:$J$5)) -> 0.23 | K19: =IF(OR(K$9>($C19+5),(K$9-$C19)<0),"",_xlfn.XLOOKUP(K$9-$C18,ChurnMatrix!$E$4:$J$4,ChurnMatrix!$E$5:$J$5)) -> 0.11 | ... M19: =IF(OR(M$9>($C19+5),(M$9-$C19)<0),"",_xlfn.XLOOKUP(M$9-$C18,ChurnMatrix!$E$4:$J$4,ChurnMatrix!$E$5:$J$5))
C20: =C19+1 -> 5 | D20: =IF(OR(D$9>($C20+5),(D$9-$C20)<0),"",_xlfn.XLOOKUP(D$9-$C19,ChurnMatrix!$E$4:$J$4,ChurnMatrix!$E$5:$J$5)) | E20: =IF(OR(E$9>($C20+5),(E$9-$C20)<0),"",_xlfn.XLOOKUP(E$9-$C19,ChurnMatrix!$E$4:$J$4,ChurnMatrix!$E$5:$J$5)) | F20: =IF(OR(F$9>($C20+5),(F$9-$C20)<0),"",_xlfn.XLOOKUP(F$9-$C19,ChurnMatrix!$E$4:$J$4,ChurnMatrix!$E$5:$J$5)) | G20: =IF(OR(G$9>($C20+5),(G$9-$C20)<0),"",_xlfn.XLOOKUP(G$9-$C19,ChurnMatrix!$E$4:$J$4,ChurnMatrix!$E$5:$J$5)) | H20: =IF(OR(H$9>($C20+5),(H$9-$C20)<0),"",_xlfn.XLOOKUP(H$9-$C19,ChurnMatrix!$E$4:$J$4,ChurnMatrix!$E$5:$J$5)) -> 0.56 | I20: =IF(OR(I$9>($C20+5),(I$9-$C20)<0),"",_xlfn.XLOOKUP(I$9-$C19,ChurnMatrix!$E$4:$J$4,ChurnMatrix!$E$5:$J$5)) -> 0.25 | J20: =IF(OR(J$9>($C20+5),(J$9-$C20)<0),"",_xlfn.XLOOKUP(J$9-$C19,ChurnMatrix!$E$4:$J$4,ChurnMatrix!$E$5:$J$5)) -> 0.25 | K20: =IF(OR(K$9>($C20+5),(K$9-$C20)<0),"",_xlfn.XLOOKUP(K$9-$C19,ChurnMatrix!$E$4:$J$4,ChurnMatrix!$E$5:$J$5)) -> 0.23 | ... M20: =IF(OR(M$9>($C20+5),(M$9-$C20)<0),"",_xlfn.XLOOKUP(M$9-$C19,ChurnMatrix!$E$4:$J$4,ChurnMatrix!$E$5:$J$5)) -> 0.11
C21: =C20+1 -> 6 | D21: =IF(OR(D$9>($C21+5),(D$9-$C21)<0),"",_xlfn.XLOOKUP(D$9-$C20,ChurnMatrix!$E$4:$J$4,ChurnMatrix!$E$5:$J$5)) | E21: =IF(OR(E$9>($C21+5),(E$9-$C21)<0),"",_xlfn.XLOOKUP(E$9-$C20,ChurnMatrix!$E$4:$J$4,ChurnMatrix!$E$5:$J$5)) | F21: =IF(OR(F$9>($C21+5),(F$9-$C21)<0),"",_xlfn.XLOOKUP(F$9-$C20,ChurnMatrix!$E$4:$J$4,ChurnMatrix!$E$5:$J$5)) | G21: =IF(OR(G$9>($C21+5),(G$9-$C21)<0),"",_xlfn.XLOOKUP(G$9-$C20,ChurnMatrix!$E$4:$J$4,ChurnMatrix!$E$5:$J$5)) | H21: =IF(OR(H$9>($C21+5),(H$9-$C21)<0),"",_xlfn.XLOOKUP(H$9-$C20,ChurnMatrix!$E$4:$J$4,ChurnMatrix!$E$5:$J$5)) | I21: =IF(OR(I$9>($C21+5),(I$9-$C21)<0),"",_xlfn.XLOOKUP(I$9-$C20,ChurnMatrix!$E$4:$J$4,ChurnMatrix!$E$5:$J$5)) -> 0.56 | J21: =IF(OR(J$9>($C21+5),(J$9-$C21)<0),"",_xlfn.XLOOKUP(J$9-$C20,ChurnMatrix!$E$4:$J$4,ChurnMatrix!$E$5:$J$5)) -> 0.25 | K21: =IF(OR(K$9>($C21+5),(K$9-$C21)<0),"",_xlfn.XLOOKUP(K$9-$C20,ChurnMatrix!$E$4:$J$4,ChurnMatrix!$E$5:$J$5)) -> 0.25 | ... M21: =IF(OR(M$9>($C21+5),(M$9-$C21)<0),"",_xlfn.XLOOKUP(M$9-$C20,ChurnMatrix!$E$4:$J$4,ChurnMatrix!$E$5:$J$5)) -> 0.11
C22: =C21+1 -> 7 | D22: =IF(OR(D$9>($C22+5),(D$9-$C22)<0),"",_xlfn.XLOOKUP(D$9-$C21,ChurnMatrix!$E$4:$J$4,ChurnMatrix!$E$5:$J$5)) | E22: =IF(OR(E$9>($C22+5),(E$9-$C22)<0),"",_xlfn.XLOOKUP(E$9-$C21,ChurnMatrix!$E$4:$J$4,ChurnMatrix!$E$5:$J$5)) | F22: =IF(OR(F$9>($C22+5),(F$9-$C22)<0),"",_xlfn.XLOOKUP(F$9-$C21,ChurnMatrix!$E$4:$J$4,ChurnMatrix!$E$5:$J$5)) | G22: =IF(OR(G$9>($C22+5),(G$9-$C22)<0),"",_xlfn.XLOOKUP(G$9-$C21,ChurnMatrix!$E$4:$J$4,ChurnMatrix!$E$5:$J$5)) | H22: =IF(OR(H$9>($C22+5),(H$9-$C22)<0),"",_xlfn.XLOOKUP(H$9-$C21,ChurnMatrix!$E$4:$J$4,ChurnMatrix!$E$5:$J$5)) | I22: =IF(OR(I$9>($C22+5),(I$9-$C22)<0),"",_xlfn.XLOOKUP(I$9-$C21,ChurnMatrix!$E$4:$J$4,ChurnMatrix!$E$5:$J$5)) | J22: =IF(OR(J$9>($C22+5),(J$9-$C22)<0),"",_xlfn.XLOOKUP(J$9-$C21,ChurnMatrix!$E$4:$J$4,ChurnMatrix!$E$5:$J$5)) -> 0.56 | K22: =IF(OR(K$9>($C22+5),(K$9-$C22)<0),"",_xlfn.XLOOKUP(K$9-$C21,ChurnMatrix!$E$4:$J$4,ChurnMatrix!$E$5:$J$5)) -> 0.25 | ... M22: =IF(OR(M$9>($C22+5),(M$9-$C22)<0),"",_xlfn.XLOOKUP(M$9-$C21,ChurnMatrix!$E$4:$J$4,ChurnMatrix!$E$5:$J$5)) -> 0.23
C23: =C22+1 -> 8 | D23: =IF(OR(D$9>($C23+5),(D$9-$C23)<0),"",_xlfn.XLOOKUP(D$9-$C22,ChurnMatrix!$E$4:$J$4,ChurnMatrix!$E$5:$J$5)) | E23: =IF(OR(E$9>($C23+5),(E$9-$C23)<0),"",_xlfn.XLOOKUP(E$9-$C22,ChurnMatrix!$E$4:$J$4,ChurnMatrix!$E$5:$J$5)) | F23: =IF(OR(F$9>($C23+5),(F$9-$C23)<0),"",_xlfn.XLOOKUP(F$9-$C22,ChurnMatrix!$E$4:$J$4,ChurnMatrix!$E$5:$J$5)) | G23: =IF(OR(G$9>($C23+5),(G$9-$C23)<0),"",_xlfn.XLOOKUP(G$9-$C22,ChurnMatrix!$E$4:$J$4,ChurnMatrix!$E$5:$J$5)) | H23: =IF(OR(H$9>($C23+5),(H$9-$C23)<0),"",_xlfn.XLOOKUP(H$9-$C22,ChurnMatrix!$E$4:$J$4,ChurnMatrix!$E$5:$J$5)) | I23: =IF(OR(I$9>($C23+5),(I$9-$C23)<0),"",_xlfn.XLOOKUP(I$9-$C22,ChurnMatrix!$E$4:$J$4,ChurnMatrix!$E$5:$J$5)) | J23: =IF(OR(J$9>($C23+5),(J$9-$C23)<0),"",_xlfn.XLOOKUP(J$9-$C22,ChurnMatrix!$E$4:$J$4,ChurnMatrix!$E$5:$J$5)) | K23: =IF(OR(K$9>($C23+5),(K$9-$C23)<0),"",_xlfn.XLOOKUP(K$9-$C22,ChurnMatrix!$E$4:$J$4,ChurnMatrix!$E$5:$J$5)) -> 0.56 | ... M23: =IF(OR(M$9>($C23+5),(M$9-$C23)<0),"",_xlfn.XLOOKUP(M$9-$C22,ChurnMatrix!$E$4:$J$4,ChurnMatrix!$E$5:$J$5)) -> 0.25
C24: =C23+1 -> 9 | D24: =IF(OR(D$9>($C24+5),(D$9-$C24)<0),"",_xlfn.XLOOKUP(D$9-$C23,ChurnMatrix!$E$4:$J$4,ChurnMatrix!$E$5:$J$5)) | E24: =IF(OR(E$9>($C24+5),(E$9-$C24)<0),"",_xlfn.XLOOKUP(E$9-$C23,ChurnMatrix!$E$4:$J$4,ChurnMatrix!$E$5:$J$5)) | F24: =IF(OR(F$9>($C24+5),(F$9-$C24)<0),"",_xlfn.XLOOKUP(F$9-$C23,ChurnMatrix!$E$4:$J$4,ChurnMatrix!$E$5:$J$5)) | G24: =IF(OR(G$9>($C24+5),(G$9-$C24)<0),"",_xlfn.XLOOKUP(G$9-$C23,ChurnMatrix!$E$4:$J$4,ChurnMatrix!$E$5:$J$5)) | H24: =IF(OR(H$9>($C24+5),(H$9-$C24)<0),"",_xlfn.XLOOKUP(H$9-$C23,ChurnMatrix!$E$4:$J$4,ChurnMatrix!$E$5:$J$5)) | I24: =IF(OR(I$9>($C24+5),(I$9-$C24)<0),"",_xlfn.XLOOKUP(I$9-$C23,ChurnMatrix!$E$4:$J$4,ChurnMatrix!$E$5:$J$5)) | J24: =IF(OR(J$9>($C24+5),(J$9-$C24)<0),"",_xlfn.XLOOKUP(J$9-$C23,ChurnMatrix!$E$4:$J$4,ChurnMatrix!$E$5:$J$5)) | K24: =IF(OR(K$9>($C24+5),(K$9-$C24)<0),"",_xlfn.XLOOKUP(K$9-$C23,ChurnMatrix!$E$4:$J$4,ChurnMatrix!$E$5:$J$5)) | ... M24: =IF(OR(M$9>($C24+5),(M$9-$C24)<0),"",_xlfn.XLOOKUP(M$9-$C23,ChurnMatrix!$E$4:$J$4,ChurnMatrix!$E$5:$J$5)) -> 0.25
C25: =C24+1 -> 10 | D25: =IF(OR(D$9>($C25+5),(D$9-$C25)<0),"",_xlfn.XLOOKUP(D$9-$C24,ChurnMatrix!$E$4:$J$4,ChurnMatrix!$E$5:$J$5)) | E25: =IF(OR(E$9>($C25+5),(E$9-$C25)<0),"",_xlfn.XLOOKUP(E$9-$C24,ChurnMatrix!$E$4:$J$4,ChurnMatrix!$E$5:$J$5)) | F25: =IF(OR(F$9>($C25+5),(F$9-$C25)<0),"",_xlfn.XLOOKUP(F$9-$C24,ChurnMatrix!$E$4:$J$4,ChurnMatrix!$E$5:$J$5)) | G25: =IF(OR(G$9>($C25+5),(G$9-$C25)<0),"",_xlfn.XLOOKUP(G$9-$C24,ChurnMatrix!$E$4:$J$4,ChurnMatrix!$E$5:$J$5)) | H25: =IF(OR(H$9>($C25+5),(H$9-$C25)<0),"",_xlfn.XLOOKUP(H$9-$C24,ChurnMatrix!$E$4:$J$4,ChurnMatrix!$E$5:$J$5)) | I25: =IF(OR(I$9>($C25+5),(I$9-$C25)<0),"",_xlfn.XLOOKUP(I$9-$C24,ChurnMatrix!$E$4:$J$4,ChurnMatrix!$E$5:$J$5)) | J25: =IF(OR(J$9>($C25+5),(J$9-$C25)<0),"",_xlfn.XLOOKUP(J$9-$C24,ChurnMatrix!$E$4:$J$4,ChurnMatrix!$E$5:$J$5)) | K25: =IF(OR(K$9>($C25+5),(K$9-$C25)<0),"",_xlfn.XLOOKUP(K$9-$C24,ChurnMatrix!$E$4:$J$4,ChurnMatrix!$E$5:$J$5)) | ... M25: =IF(OR(M$9>($C25+5),(M$9-$C25)<0),"",_xlfn.XLOOKUP(M$9-$C24,ChurnMatrix!$E$4:$J$4,ChurnMatrix!$E$5:$J$5)) -> 0.56
C26: =C25+1 -> 11 | D26: =IF(OR(D$9>($C26+5),(D$9-$C26)<0),"",_xlfn.XLOOKUP(D$9-$C25,ChurnMatrix!$E$4:$J$4,ChurnMatrix!$E$5:$J$5)) | E26: =IF(OR(E$9>($C26+5),(E$9-$C26)<0),"",_xlfn.XLOOKUP(E$9-$C25,ChurnMatrix!$E$4:$J$4,ChurnMatrix!$E$5:$J$5)) | F26: =IF(OR(F$9>($C26+5),(F$9-$C26)<0),"",_xlfn.XLOOKUP(F$9-$C25,ChurnMatrix!$E$4:$J$4,ChurnMatrix!$E$5:$J$5)) | G26: =IF(OR(G$9>($C26+5),(G$9-$C26)<0),"",_xlfn.XLOOKUP(G$9-$C25,ChurnMatrix!$E$4:$J$4,ChurnMatrix!$E$5:$J$5)) | H26: =IF(OR(H$9>($C26+5),(H$9-$C26)<0),"",_xlfn.XLOOKUP(H$9-$C25,ChurnMatrix!$E$4:$J$4,ChurnMatrix!$E$5:$J$5)) | I26: =IF(OR(I$9>($C26+5),(I$9-$C26)<0),"",_xlfn.XLOOKUP(I$9-$C25,ChurnMatrix!$E$4:$J$4,ChurnMatrix!$E$5:$J$5)) | J26: =IF(OR(J$9>($C26+5),(J$9-$C26)<0),"",_xlfn.XLOOKUP(J$9-$C25,ChurnMatrix!$E$4:$J$4,ChurnMatrix!$E$5:$J$5)) | K26: =IF(OR(K$9>($C26+5),(K$9-$C26)<0),"",_xlfn.XLOOKUP(K$9-$C25,ChurnMatrix!$E$4:$J$4,ChurnMatrix!$E$5:$J$5)) | ... M26: =IF(OR(M$9>($C26+5),(M$9-$C26)<0),"",_xlfn.XLOOKUP(M$9-$C25,ChurnMatrix!$E$4:$J$4,ChurnMatrix!$E$5:$J$5))
C27: =C26+1 -> 12 | D27: =IF(OR(D$9>($C27+5),(D$9-$C27)<0),"",_xlfn.XLOOKUP(D$9-$C26,ChurnMatrix!$E$4:$J$4,ChurnMatrix!$E$5:$J$5)) | E27: =IF(OR(E$9>($C27+5),(E$9-$C27)<0),"",_xlfn.XLOOKUP(E$9-$C26,ChurnMatrix!$E$4:$J$4,ChurnMatrix!$E$5:$J$5)) | F27: =IF(OR(F$9>($C27+5),(F$9-$C27)<0),"",_xlfn.XLOOKUP(F$9-$C26,ChurnMatrix!$E$4:$J$4,ChurnMatrix!$E$5:$J$5)) | G27: =IF(OR(G$9>($C27+5),(G$9-$C27)<0),"",_xlfn.XLOOKUP(G$9-$C26,ChurnMatrix!$E$4:$J$4,ChurnMatrix!$E$5:$J$5)) | H27: =IF(OR(H$9>($C27+5),(H$9-$C27)<0),"",_xlfn.XLOOKUP(H$9-$C26,ChurnMatrix!$E$4:$J$4,ChurnMatrix!$E$5:$J$5)) | I27: =IF(OR(I$9>($C27+5),(I$9-$C27)<0),"",_xlfn.XLOOKUP(I$9-$C26,ChurnMatrix!$E$4:$J$4,ChurnMatrix!$E$5:$J$5)) | J27: =IF(OR(J$9>($C27+5),(J$9-$C27)<0),"",_xlfn.XLOOKUP(J$9-$C26,ChurnMatrix!$E$4:$J$4,ChurnMatrix!$E$5:$J$5)) | K27: =IF(OR(K$9>($C27+5),(K$9-$C27)<0),"",_xlfn.XLOOKUP(K$9-$C26,ChurnMatrix!$E$4:$J$4,ChurnMatrix!$E$5:$J$5)) | ... M27: =IF(OR(M$9>($C27+5),(M$9-$C27)<0),"",_xlfn.XLOOKUP(M$9-$C26,ChurnMatrix!$E$4:$J$4,ChurnMatrix!$E$5:$J$5))
C28: =C27+1 -> 13 | D28: =IF(OR(D$9>($C28+5),(D$9-$C28)<0),"",_xlfn.XLOOKUP(D$9-$C27,ChurnMatrix!$E$4:$J$4,ChurnMatrix!$E$5:$J$5)) | E28: =IF(OR(E$9>($C28+5),(E$9-$C28)<0),"",_xlfn.XLOOKUP(E$9-$C27,ChurnMatrix!$E$4:$J$4,ChurnMatrix!$E$5:$J$5)) | F28: =IF(OR(F$9>($C28+5),(F$9-$C28)<0),"",_xlfn.XLOOKUP(F$9-$C27,ChurnMatrix!$E$4:$J$4,ChurnMatrix!$E$5:$J$5)) | G28: =IF(OR(G$9>($C28+5),(G$9-$C28)<0),"",_xlfn.XLOOKUP(G$9-$C27,ChurnMatrix!$E$4:$J$4,ChurnMatrix!$E$5:$J$5)) | H28: =IF(OR(H$9>($C28+5),(H$9-$C28)<0),"",_xlfn.XLOOKUP(H$9-$C27,ChurnMatrix!$E$4:$J$4,ChurnMatrix!$E$5:$J$5)) | I28: =IF(OR(I$9>($C28+5),(I$9-$C28)<0),"",_xlfn.XLOOKUP(I$9-$C27,ChurnMatrix!$E$4:$J$4,ChurnMatrix!$E$5:$J$5)) | J28: =IF(OR(J$9>($C28+5),(J$9-$C28)<0),"",_xlfn.XLOOKUP(J$9-$C27,ChurnMatrix!$E$4:$J$4,ChurnMatrix!$E$5:$J$5)) | K28: =IF(OR(K$9>($C28+5),(K$9-$C28)<0),"",_xlfn.XLOOKUP(K$9-$C27,ChurnMatrix!$E$4:$J$4,ChurnMatrix!$E$5:$J$5)) | ... M28: =IF(OR(M$9>($C28+5),(M$9-$C28)<0),"",_xlfn.XLOOKUP(M$9-$C27,ChurnMatrix!$E$4:$J$4,ChurnMatrix!$E$5:$J$5))
... C39: =C38+1 -> 24 | D39: =IF(OR(D$9>($C39+5),(D$9-$C39)<0),"",_xlfn.XLOOKUP(D$9-$C38,ChurnMatrix!$E$4:$J$4,ChurnMatrix!$E$5:$J$5)) | E39: =IF(OR(E$9>($C39+5),(E$9-$C39)<0),"",_xlfn.XLOOKUP(E$9-$C38,ChurnMatrix!$E$4:$J$4,ChurnMatrix!$E$5:$J$5)) | F39: =IF(OR(F$9>($C39+5),(F$9-$C39)<0),"",_xlfn.XLOOKUP(F$9-$C38,ChurnMatrix!$E$4:$J$4,ChurnMatrix!$E$5:$J$5)) | G39: =IF(OR(G$9>($C39+5),(G$9-$C39)<0),"",_xlfn.XLOOKUP(G$9-$C38,ChurnMatrix!$E$4:$J$4,ChurnMatrix!$E$5:$J$5)) | H39: =IF(OR(H$9>($C39+5),(H$9-$C39)<0),"",_xlfn.XLOOKUP(H$9-$C38,ChurnMatrix!$E$4:$J$4,ChurnMatrix!$E$5:$J$5)) | I39: =IF(OR(I$9>($C39+5),(I$9-$C39)<0),"",_xlfn.XLOOKUP(I$9-$C38,ChurnMatrix!$E$4:$J$4,ChurnMatrix!$E$5:$J$5)) | J39: =IF(OR(J$9>($C39+5),(J$9-$C39)<0),"",_xlfn.XLOOKUP(J$9-$C38,ChurnMatrix!$E$4:$J$4,ChurnMatrix!$E$5:$J$5)) | K39: =IF(OR(K$9>($C39+5),(K$9-$C39)<0),"",_xlfn.XLOOKUP(K$9-$C38,ChurnMatrix!$E$4:$J$4,ChurnMatrix!$E$5:$J$5)) | ... M39: =IF(OR(M$9>($C39+5),(M$9-$C39)<0),"",_xlfn.XLOOKUP(M$9-$C38,ChurnMatrix!$E$4:$J$4,ChurnMatrix!$E$5:$J$5))
C44: Cohort Count
C45: 1 | D45: =IFERROR(IF(D$9<($C45+6),HLOOKUP($C45,$D$9:$AA$11,3,FALSE)*D16,C45),"") -> 728 | E45: =IFERROR(IF(E$9<($C45+6),HLOOKUP($C45,$D$9:$AA$11,3,FALSE)*E16,D45),"") -> 325 | F45: =IFERROR(IF(F$9<($C45+6),HLOOKUP($C45,$D$9:$AA$11,3,FALSE)*F16,E45),"") -> 325 | G45: =IFERROR(IF(G$9<($C45+6),HLOOKUP($C45,$D$9:$AA$11,3,FALSE)*G16,F45),"") -> 299 | H45: =IFERROR(IF(H$9<($C45+6),HLOOKUP($C45,$D$9:$AA$11,3,FALSE)*H16,G45),"") -> 143 | I45: =IFERROR(IF(I$9<($C45+6),HLOOKUP($C45,$D$9:$AA$11,3,FALSE)*I16,H45),"") -> 143 | J45: =IFERROR(IF(J$9<($C45+6),HLOOKUP($C45,$D$9:$AA$11,3,FALSE)*J16,I45),"") -> 143 | K45: =IFERROR(IF(K$9<($C45+6),HLOOKUP($C45,$D$9:$AA$11,3,FALSE)*K16,J45),"") -> 143 | ... M45: =IFERROR(IF(M$9<($C45+6),HLOOKUP($C45,$D$9:$AA$11,3,FALSE)*M16,L45),"") -> 143
C46: =C45+1 -> 2 | D46: =IFERROR(IF(D$9<($C46+6),HLOOKUP($C46,$D$9:$AA$11,3,FALSE)*D17,C46),"") | E46: =IFERROR(IF(E$9<($C46+6),HLOOKUP($C46,$D$9:$AA$11,3,FALSE)*E17,D46),"") -> 1120 | F46: =IFERROR(IF(F$9<($C46+6),HLOOKUP($C46,$D$9:$AA$11,3,FALSE)*F17,E46),"") -> 500 | G46: =IFERROR(IF(G$9<($C46+6),HLOOKUP($C46,$D$9:$AA$11,3,FALSE)*G17,F46),"") -> 500 | H46: =IFERROR(IF(H$9<($C46+6),HLOOKUP($C46,$D$9:$AA$11,3,FALSE)*H17,G46),"") -> 460 | I46: =IFERROR(IF(I$9<($C46+6),HLOOKUP($C46,$D$9:$AA$11,3,FALSE)*I17,H46),"") -> 220 | J46: =IFERROR(IF(J$9<($C46+6),HLOOKUP($C46,$D$9:$AA$11,3,FALSE)*J17,I46),"") -> 220 | K46: =IFERROR(IF(K$9<($C46+6),HLOOKUP($C46,$D$9:$AA$11,3,FALSE)*K17,J46),"") -> 220 | ... M46: =IFERROR(IF(M$9<($C46+6),HLOOKUP($C46,$D$9:$AA$11,3,FALSE)*M17,L46),"") -> 220
C47: =C46+1 -> 3 | D47: =IFERROR(IF(D$9<($C47+6),HLOOKUP($C47,$D$9:$AA$11,3,FALSE)*D18,C47),"") | E47: =IFERROR(IF(E$9<($C47+6),HLOOKUP($C47,$D$9:$AA$11,3,FALSE)*E18,D47),"") | F47: =IFERROR(IF(F$9<($C47+6),HLOOKUP($C47,$D$9:$AA$11,3,FALSE)*F18,E47),"") -> 1848 | G47: =IFERROR(IF(G$9<($C47+6),HLOOKUP($C47,$D$9:$AA$11,3,FALSE)*G18,F47),"") -> 825 | H47: =IFERROR(IF(H$9<($C47+6),HLOOKUP($C47,$D$9:$AA$11,3,FALSE)*H18,G47),"") -> 825 | I47: =IFERROR(IF(I$9<($C47+6),HLOOKUP($C47,$D$9:$AA$11,3,FALSE)*I18,H47),"") -> 759 | J47: =IFERROR(IF(J$9<($C47+6),HLOOKUP($C47,$D$9:$AA$11,3,FALSE)*J18,I47),"") -> 363 | K47: =IFERROR(IF(K$9<($C47+6),HLOOKUP($C47,$D$9:$AA$11,3,FALSE)*K18,J47),"") -> 363 | ... M47: =IFERROR(IF(M$9<($C47+6),HLOOKUP($C47,$D$9:$AA$11,3,FALSE)*M18,L47),"") -> 363
C48: =C47+1 -> 4 | D48: =IFERROR(IF(D$9<($C48+6),HLOOKUP($C48,$D$9:$AA$11,3,FALSE)*D19,C48),"") | E48: =IFERROR(IF(E$9<($C48+6),HLOOKUP($C48,$D$9:$AA$11,3,FALSE)*E19,D48),"") | F48: =IFERROR(IF(F$9<($C48+6),HLOOKUP($C48,$D$9:$AA$11,3,FALSE)*F19,E48),"") | G48: =IFERROR(IF(G$9<($C48+6),HLOOKUP($C48,$D$9:$AA$11,3,FALSE)*G19,F48),"") -> 1940.4 | H48: =IFERROR(IF(H$9<($C48+6),HLOOKUP($C48,$D$9:$AA$11,3,FALSE)*H19,G48),"") -> 866.25 | I48: =IFERROR(IF(I$9<($C48+6),HLOOKUP($C48,$D$9:$AA$11,3,FALSE)*I19,H48),"") -> 866.25 | J48: =IFERROR(IF(J$9<($C48+6),HLOOKUP($C48,$D$9:$AA$11,3,FALSE)*J19,I48),"") -> 796.95 | K48: =IFERROR(IF(K$9<($C48+6),HLOOKUP($C48,$D$9:$AA$11,3,FALSE)*K19,J48),"") -> 381.15 | ... M48: =IFERROR(IF(M$9<($C48+6),HLOOKUP($C48,$D$9:$AA$11,3,FALSE)*M19,L48),"") -> 381.15
C49: =C48+1 -> 5 | D49: =IFERROR(IF(D$9<($C49+6),HLOOKUP($C49,$D$9:$AA$11,3,FALSE)*D20,C49),"") | E49: =IFERROR(IF(E$9<($C49+6),HLOOKUP($C49,$D$9:$AA$11,3,FALSE)*E20,D49),"") | F49: =IFERROR(IF(F$9<($C49+6),HLOOKUP($C49,$D$9:$AA$11,3,FALSE)*F20,E49),"") | G49: =IFERROR(IF(G$9<($C49+6),HLOOKUP($C49,$D$9:$AA$11,3,FALSE)*G20,F49),"") | H49: =IFERROR(IF(H$9<($C49+6),HLOOKUP($C49,$D$9:$AA$11,3,FALSE)*H20,G49),"") -> 2037.42 | I49: =IFERROR(IF(I$9<($C49+6),HLOOKUP($C49,$D$9:$AA$11,3,FALSE)*I20,H49),"") -> 909.5625 | J49: =IFERROR(IF(J$9<($C49+6),HLOOKUP($C49,$D$9:$AA$11,3,FALSE)*J20,I49),"") -> 909.5625 | K49: =IFERROR(IF(K$9<($C49+6),HLOOKUP($C49,$D$9:$AA$11,3,FALSE)*K20,J49),"") -> 836.7975 | ... M49: =IFERROR(IF(M$9<($C49+6),HLOOKUP($C49,$D$9:$AA$11,3,FALSE)*M20,L49),"") -> 400.2075
C50: =C49+1 -> 6 | D50: =IFERROR(IF(D$9<($C50+6),HLOOKUP($C50,$D$9:$AA$11,3,FALSE)*D21,C50),"") | E50: =IFERROR(IF(E$9<($C50+6),HLOOKUP($C50,$D$9:$AA$11,3,FALSE)*E21,D50),"") | F50: =IFERROR(IF(F$9<($C50+6),HLOOKUP($C50,$D$9:$AA$11,3,FALSE)*F21,E50),"") | G50: =IFERROR(IF(G$9<($C50+6),HLOOKUP($C50,$D$9:$AA$11,3,FALSE)*G21,F50),"") | H50: =IFERROR(IF(H$9<($C50+6),HLOOKUP($C50,$D$9:$AA$11,3,FALSE)*H21,G50),"") | I50: =IFERROR(IF(I$9<($C50+6),HLOOKUP($C50,$D$9:$AA$11,3,FALSE)*I21,H50),"") -> 2139.291 | J50: =IFERROR(IF(J$9<($C50+6),HLOOKUP($C50,$D$9:$AA$11,3,FALSE)*J21,I50),"") -> 955.04062 | K50: =IFERROR(IF(K$9<($C50+6),HLOOKUP($C50,$D$9:$AA$11,3,FALSE)*K21,J50),"") -> 955.04062 | ... M50: =IFERROR(IF(M$9<($C50+6),HLOOKUP($C50,$D$9:$AA$11,3,FALSE)*M21,L50),"") -> 420.21787
C51: =C50+1 -> 7 | D51: =IFERROR(IF(D$9<($C51+6),HLOOKUP($C51,$D$9:$AA$11,3,FALSE)*D22,C51),"") | E51: =IFERROR(IF(E$9<($C51+6),HLOOKUP($C51,$D$9:$AA$11,3,FALSE)*E22,D51),"") | F51: =IFERROR(IF(F$9<($C51+6),HLOOKUP($C51,$D$9:$AA$11,3,FALSE)*F22,E51),"") | G51: =IFERROR(IF(G$9<($C51+6),HLOOKUP($C51,$D$9:$AA$11,3,FALSE)*G22,F51),"") | H51: =IFERROR(IF(H$9<($C51+6),HLOOKUP($C51,$D$9:$AA$11,3,FALSE)*H22,G51),"") | I51: =IFERROR(IF(I$9<($C51+6),HLOOKUP($C51,$D$9:$AA$11,3,FALSE)*I22,H51),"") | J51: =IFERROR(IF(J$9<($C51+6),HLOOKUP($C51,$D$9:$AA$11,3,FALSE)*J22,I51),"") -> 2246.2556 | K51: =IFERROR(IF(K$9<($C51+6),HLOOKUP($C51,$D$9:$AA$11,3,FALSE)*K22,J51),"") -> 1002.7927 | ... M51: =IFERROR(IF(M$9<($C51+6),HLOOKUP($C51,$D$9:$AA$11,3,FALSE)*M22,L51),"") -> 922.56924
C52: =C51+1 -> 8 | D52: =IFERROR(IF(D$9<($C52+6),HLOOKUP($C52,$D$9:$AA$11,3,FALSE)*D23,C52),"") | E52: =IFERROR(IF(E$9<($C52+6),HLOOKUP($C52,$D$9:$AA$11,3,FALSE)*E23,D52),"") | F52: =IFERROR(IF(F$9<($C52+6),HLOOKUP($C52,$D$9:$AA$11,3,FALSE)*F23,E52),"") | G52: =IFERROR(IF(G$9<($C52+6),HLOOKUP($C52,$D$9:$AA$11,3,FALSE)*G23,F52),"") | H52: =IFERROR(IF(H$9<($C52+6),HLOOKUP($C52,$D$9:$AA$11,3,FALSE)*H23,G52),"") | I52: =IFERROR(IF(I$9<($C52+6),HLOOKUP($C52,$D$9:$AA$11,3,FALSE)*I23,H52),"") | J52: =IFERROR(IF(J$9<($C52+6),HLOOKUP($C52,$D$9:$AA$11,3,FALSE)*J23,I52),"") | K52: =IFERROR(IF(K$9<($C52+6),HLOOKUP($C52,$D$9:$AA$11,3,FALSE)*K23,J52),"") -> 2358.5683 | ... M52: =IFERROR(IF(M$9<($C52+6),HLOOKUP($C52,$D$9:$AA$11,3,FALSE)*M23,L52),"") -> 1052.9323
C53: =C52+1 -> 9 | D53: =IFERROR(IF(D$9<($C53+6),HLOOKUP($C53,$D$9:$AA$11,3,FALSE)*D24,C53),"") | E53: =IFERROR(IF(E$9<($C53+6),HLOOKUP($C53,$D$9:$AA$11,3,FALSE)*E24,D53),"") | F53: =IFERROR(IF(F$9<($C53+6),HLOOKUP($C53,$D$9:$AA$11,3,FALSE)*F24,E53),"") | G53: =IFERROR(IF(G$9<($C53+6),HLOOKUP($C53,$D$9:$AA$11,3,FALSE)*G24,F53),"") | H53: =IFERROR(IF(H$9<($C53+6),HLOOKUP($C53,$D$9:$AA$11,3,FALSE)*H24,G53),"") | I53: =IFERROR(IF(I$9<($C53+6),HLOOKUP($C53,$D$9:$AA$11,3,FALSE)*I24,H53),"") | J53: =IFERROR(IF(J$9<($C53+6),HLOOKUP($C53,$D$9:$AA$11,3,FALSE)*J24,I53),"") | K53: =IFERROR(IF(K$9<($C53+6),HLOOKUP($C53,$D$9:$AA$11,3,FALSE)*K24,J53),"") | ... M53: =IFERROR(IF(M$9<($C53+6),HLOOKUP($C53,$D$9:$AA$11,3,FALSE)*M24,L53),"") -> 1105.5789
C54: =C53+1 -> 10 | D54: =IFERROR(IF(D$9<($C54+6),HLOOKUP($C54,$D$9:$AA$11,3,FALSE)*D25,C54),"") | E54: =IFERROR(IF(E$9<($C54+6),HLOOKUP($C54,$D$9:$AA$11,3,FALSE)*E25,D54),"") | F54: =IFERROR(IF(F$9<($C54+6),HLOOKUP($C54,$D$9:$AA$11,3,FALSE)*F25,E54),"") | G54: =IFERROR(IF(G$9<($C54+6),HLOOKUP($C54,$D$9:$AA$11,3,FALSE)*G25,F54),"") | H54: =IFERROR(IF(H$9<($C54+6),HLOOKUP($C54,$D$9:$AA$11,3,FALSE)*H25,G54),"") | I54: =IFERROR(IF(I$9<($C54+6),HLOOKUP($C54,$D$9:$AA$11,3,FALSE)*I25,H54),"") | J54: =IFERROR(IF(J$9<($C54+6),HLOOKUP($C54,$D$9:$AA$11,3,FALSE)*J25,I54),"") | K54: =IFERROR(IF(K$9<($C54+6),HLOOKUP($C54,$D$9:$AA$11,3,FALSE)*K25,J54),"") | ... M54: =IFERROR(IF(M$9<($C54+6),HLOOKUP($C54,$D$9:$AA$11,3,FALSE)*M25,L54),"") -> 2600.3216
C55: =C54+1 -> 11 | D55: =IFERROR(IF(D$9<($C55+6),HLOOKUP($C55,$D$9:$AA$11,3,FALSE)*D26,C55),"") | E55: =IFERROR(IF(E$9<($C55+6),HLOOKUP($C55,$D$9:$AA$11,3,FALSE)*E26,D55),"") | F55: =IFERROR(IF(F$9<($C55+6),HLOOKUP($C55,$D$9:$AA$11,3,FALSE)*F26,E55),"") | G55: =IFERROR(IF(G$9<($C55+6),HLOOKUP($C55,$D$9:$AA$11,3,FALSE)*G26,F55),"") | H55: =IFERROR(IF(H$9<($C55+6),HLOOKUP($C55,$D$9:$AA$11,3,FALSE)*H26,G55),"") | I55: =IFERROR(IF(I$9<($C55+6),HLOOKUP($C55,$D$9:$AA$11,3,FALSE)*I26,H55),"") | J55: =IFERROR(IF(J$9<($C55+6),HLOOKUP($C55,$D$9:$AA$11,3,FALSE)*J26,I55),"") | K55: =IFERROR(IF(K$9<($C55+6),HLOOKUP($C55,$D$9:$AA$11,3,FALSE)*K26,J55),"") | ... M55: =IFERROR(IF(M$9<($C55+6),HLOOKUP($C55,$D$9:$AA$11,3,FALSE)*M26,L55),"")
C56: =C55+1 -> 12 | D56: =IFERROR(IF(D$9<($C56+6),HLOOKUP($C56,$D$9:$AA$11,3,FALSE)*D27,C56),"") | E56: =IFERROR(IF(E$9<($C56+6),HLOOKUP($C56,$D$9:$AA$11,3,FALSE)*E27,D56),"") | F56: =IFERROR(IF(F$9<($C56+6),HLOOKUP($C56,$D$9:$AA$11,3,FALSE)*F27,E56),"") | G56: =IFERROR(IF(G$9<($C56+6),HLOOKUP($C56,$D$9:$AA$11,3,FALSE)*G27,F56),"") | H56: =IFERROR(IF(H$9<($C56+6),HLOOKUP($C56,$D$9:$AA$11,3,FALSE)*H27,G56),"") | I56: =IFERROR(IF(I$9<($C56+6),HLOOKUP($C56,$D$9:$AA$11,3,FALSE)*I27,H56),"") | J56: =IFERROR(IF(J$9<($C56+6),HLOOKUP($C56,$D$9:$AA$11,3,FALSE)*J27,I56),"") | K56: =IFERROR(IF(K$9<($C56+6),HLOOKUP($C56,$D$9:$AA$11,3,FALSE)*K27,J56),"") | ... M56: =IFERROR(IF(M$9<($C56+6),HLOOKUP($C56,$D$9:$AA$11,3,FALSE)*M27,L56),"")
C57: =C56+1 -> 13 | D57: =IFERROR(IF(D$9<($C57+6),HLOOKUP($C57,$D$9:$AA$11,3,FALSE)*D28,C57),"") | E57: =IFERROR(IF(E$9<($C57+6),HLOOKUP($C57,$D$9:$AA$11,3,FALSE)*E28,D57),"") | F57: =IFERROR(IF(F$9<($C57+6),HLOOKUP($C57,$D$9:$AA$11,3,FALSE)*F28,E57),"") | G57: =IFERROR(IF(G$9<($C57+6),HLOOKUP($C57,$D$9:$AA$11,3,FALSE)*G28,F57),"") | H57: =IFERROR(IF(H$9<($C57+6),HLOOKUP($C57,$D$9:$AA$11,3,FALSE)*H28,G57),"") | I57: =IFERROR(IF(I$9<($C57+6),HLOOKUP($C57,$D$9:$AA$11,3,FALSE)*I28,H57),"") | J57: =IFERROR(IF(J$9<($C57+6),HLOOKUP($C57,$D$9:$AA$11,3,FALSE)*J28,I57),"") | K57: =IFERROR(IF(K$9<($C57+6),HLOOKUP($C57,$D$9:$AA$11,3,FALSE)*K28,J57),"") | ... M57: =IFERROR(IF(M$9<($C57+6),HLOOKUP($C57,$D$9:$AA$11,3,FALSE)*M28,L57),"")
... C68: =C67+1 -> 24 | D68: =IFERROR(IF(D$9<($C68+6),HLOOKUP($C68,$D$9:$AA$11,3,FALSE)*D39,C68),"") | E68: =IFERROR(IF(E$9<($C68+6),HLOOKUP($C68,$D$9:$AA$11,3,FALSE)*E39,D68),"") | F68: =IFERROR(IF(F$9<($C68+6),HLOOKUP($C68,$D$9:$AA$11,3,FALSE)*F39,E68),"") | G68: =IFERROR(IF(G$9<($C68+6),HLOOKUP($C68,$D$9:$AA$11,3,FALSE)*G39,F68),"") | H68: =IFERROR(IF(H$9<($C68+6),HLOOKUP($C68,$D$9:$AA$11,3,FALSE)*H39,G68),"") | I68: =IFERROR(IF(I$9<($C68+6),HLOOKUP($C68,$D$9:$AA$11,3,FALSE)*I39,H68),"") | J68: =IFERROR(IF(J$9<($C68+6),HLOOKUP($C68,$D$9:$AA$11,3,FALSE)*J39,I68),"") | K68: =IFERROR(IF(K$9<($C68+6),HLOOKUP($C68,$D$9:$AA$11,3,FALSE)*K39,J68),"") | ... M68: =IFERROR(IF(M$9<($C68+6),HLOOKUP($C68,$D$9:$AA$11,3,FALSE)*M39,L68),"")
C72: Cohort Attrition
C73: 1 | D73: =IF(AND(D$9>($C73),D$9<($C73+6)), D45-C45,"") | E73: =IF(AND(E$9>($C73),E$9<($C73+6)), E45-D45,"") -> -403 | F73: =IF(AND(F$9>($C73),F$9<($C73+6)), F45-E45,"") -> 0 | G73: =IF(AND(G$9>($C73),G$9<($C73+6)), G45-F45,"") -> -26 | H73: =IF(AND(H$9>($C73),H$9<($C73+6)), H45-G45,"") -> -156 | I73: =IF(AND(I$9>($C73),I$9<($C73+6)), I45-H45,"") -> 0 | J73: =IF(AND(J$9>($C73),J$9<($C73+6)), J45-I45,"") | K73: =IF(AND(K$9>($C73),K$9<($C73+6)), K45-J45,"") | ... M73: =IF(AND(M$9>($C73),M$9<($C73+6)), M45-L45,"")
C74: =C73+1 -> 2 | D74: =IF(AND(D$9>($C74),D$9<($C74+6)), D46-C46,"") | E74: =IF(AND(E$9>($C74),E$9<($C74+6)), E46-D46,"") | F74: =IF(AND(F$9>($C74),F$9<($C74+6)), F46-E46,"") -> -620 | G74: =IF(AND(G$9>($C74),G$9<($C74+6)), G46-F46,"") -> 0 | H74: =IF(AND(H$9>($C74),H$9<($C74+6)), H46-G46,"") -> -40 | I74: =IF(AND(I$9>($C74),I$9<($C74+6)), I46-H46,"") -> -240 | J74: =IF(AND(J$9>($C74),J$9<($C74+6)), J46-I46,"") -> 0 | K74: =IF(AND(K$9>($C74),K$9<($C74+6)), K46-J46,"") | ... M74: =IF(AND(M$9>($C74),M$9<($C74+6)), M46-L46,"")
C75: =C74+1 -> 3 | D75: =IF(AND(D$9>($C75),D$9<($C75+6)), D47-C47,"") | E75: =IF(AND(E$9>($C75),E$9<($C75+6)), E47-D47,"") | F75: =IF(AND(F$9>($C75),F$9<($C75+6)), F47-E47,"") | G75: =IF(AND(G$9>($C75),G$9<($C75+6)), G47-F47,"") -> -1023 | H75: =IF(AND(H$9>($C75),H$9<($C75+6)), H47-G47,"") -> 0 | I75: =IF(AND(I$9>($C75),I$9<($C75+6)), I47-H47,"") -> -66 | J75: =IF(AND(J$9>($C75),J$9<($C75+6)), J47-I47,"") -> -396 | K75: =IF(AND(K$9>($C75),K$9<($C75+6)), K47-J47,"") -> 0 | ... M75: =IF(AND(M$9>($C75),M$9<($C75+6)), M47-L47,"")
C76: =C75+1 -> 4 | D76: =IF(AND(D$9>($C76),D$9<($C76+6)), D48-C48,"") | E76: =IF(AND(E$9>($C76),E$9<($C76+6)), E48-D48,"") | F76: =IF(AND(F$9>($C76),F$9<($C76+6)), F48-E48,"") | G76: =IF(AND(G$9>($C76),G$9<($C76+6)), G48-F48,"") | H76: =IF(AND(H$9>($C76),H$9<($C76+6)), H48-G48,"") -> -1074.15 | I76: =IF(AND(I$9>($C76),I$9<($C76+6)), I48-H48,"") -> 0 | J76: =IF(AND(J$9>($C76),J$9<($C76+6)), J48-I48,"") -> -69.3 | K76: =IF(AND(K$9>($C76),K$9<($C76+6)), K48-J48,"") -> -415.8 | ... M76: =IF(AND(M$9>($C76),M$9<($C76+6)), M48-L48,"")
...

Sheet ModelDrivers
C3: EV Market growth | E3: 0.05 | G3: Month | H3: User Retention
B4: Assume % of customers we could get from our potetnial pool | C4: Activation % | E4: 0.05 | G4: 1 | H4: 0.56
C5: Subscription Conversion % | E5: 0.02 | G5: =G4+1 -> 2 | H5: 0.25
G6: =G5+1 -> 3 | H6: 0.25
G7: =G6+1 -> 4 | H7: 0.23
D8: Assume Price / customer | E8: Assume % Subs in Plan | G8: =G7+1 -> 5 | H8: 0.11
C9: Plan A | D9: 100 | E9: 0.6 | G9: =G8+1 -> 6 | H9: 0.11
C10: Plan B | D10: 120 | E10: 0.3
C11: Plan C | D11: 140 | E11: =1- SUM(E9:E10) -> 0.1
C21: Fixed Monthly Information | G21: Daily Labor Costs
C22: Rent | D22: 2000 | G22: Items | H22: Rate | I22: Qty | J22: Total Pay
C23: Electric | D23: 150 | G23: Taxes | H23: 40 | I23: 8 | J23: =H23*I23 -> 320
C24: Phone | D24: 100 | G24: Tool Cost | H24: 50 | I24: 4 | J24: =H24*I24 -> 200
C25: Internet | D25: 150 | G25: Battery Replacement | H25: 89.99 | I25: 4 | J25: =H25*I25 -> 359.96
C26: Water | D26: 50 | G26: Parking Charges | H26: 25 | I26: 1 | J26: =H26*I26 -> 25
C27: Insurance | D27: 150 | G27: Recycling | H27: 89.99 | I27: 4 | J27: =H27*I27 -> 359.96
C28: Accounting/Legal | D28: 100 | G28: Meals | H28: 200 | I28: 1 | J28: =H28*I28 -> 200
C29: Advertising | D29: 250 | G29: Toll fees | H29: 8 | I29: 23 | J29: =H29*I29 -> 184
C30: Other | D30: 300 | G30: Travel Expenses | H30: 50 | I30: 11 | J30: =H30*I30 -> 550
C31: Total | D31: =SUM(D22:D30) -> 3250 | G31: Total | H31: =SUM(H23:H30) -> 552.98 | I31: 1000 | J31: =SUM(J23:J30) -> 2198.92

Sheet PB_CACHE
A1: H4sIAAAAAAAEAO2YC3RT9R3Hc+kzoeALkW1qr2KBag1N0gftivSRtNSW9JG2gF3XJumFht4m9SZhbTluqMA2cThQ5mBwcMoUJlNU5HGkOHFjOhRxPjZ22EDEeTjOzfmAHTjW/f6X/P73l5jk3KP1nB0POafJ/58mn9/r+/v9741BMBgMn8GDvbJH1hh4amr0hbw9lYFAr9gy2C8FxXqfR3Erg3lim6QEfQH/TGu+tdBsM+eb8/PEqrAcCivSTL8UDiluOU9sDHtkn7dOGmwJ9Er+mf6wLKcxvotjO1VsZwRrdkmKzy37htweWapye3ukz79zQ0ugv15aLMnqzu7zhsAN+G4qcDMiXmVWBfr63YqkZM52B3tcviFpHDjR5pbDUqPbpwQNKYaUzDWCazAYkvrMVQFZllRM0Fwj+cGgF18dt4bBeGgQeV2W9vbIt1whxedfmCf2Bb0BRfZ5tJQUsGzoyYenuNhd6C0sspTYCqT8GSUdHZm/HpPEKRpDl/Ur9SSv/cuUKKY0YG60ZdTR0d7BBMrUZEyBJ/ZnZBpIZav/x9qypspgHqpOs7+ULReqrbPaqedgNF1Il950sdZI6ZUG0xazlAipdaPoMGOnp7MnV48khSzGDFinsafRtPL1GOcPf30U2w3nrs/7FY7yMhzl89nCyOpvxGnJ/pey+UIy9UzK0zApL6Tqi0zJmlFyVp2QY+FJdFa4SsWqZkebUwqJdskTqm7KL55uKZrOnG112bPGwafmOga8kmz3u821/pC0UHGzcmlxWcwWfUEtsFoLpZKiwpIZhcVSt0fKGg/wiuqA0ucOBb/EFfvHIKjRSg3r74llqvxu6u3srHR7e0F01T5J7r6yzC4FvYqvn4Uf+88rys7HEfv+GCH1skiEZpV6fsMiZ1UwXgRPprQPIIJ4H2OjJUMtfmenIXN85DJS+Dd8nHVR+qWwm+qa7SgV8yFpJQUtgZBbFpvh7sMPiOhSCu/DN1iqMtMtO+e9tO/Q5ZUm4Z+wZ8bTGPY9xE5k0misdc4rFZ119RVNjsraFntFLO9UhGecxGIQ3o2gVA//gahvMRTxMD7qJHcte+nCg+PPvllhEt6mrp1AXjbsLI6W5lKxrWGuDc7JvoBfdPXAYRkUG8KhYMjt72a5jzFwnBuA72+a9tYwGDhGDfwdDUyG3dW8LeK7exQjz1Ej/yuN/AiCpjFPKxvmlIqFNqutwMY6rNbvDfRJ4jQnqy5IUOrOjWX/mXv6t+vSM852rgFP36SevoEG8rQGdjidCRpYeI1G3rXzIx/w/kR5ryIvH3bZKq+mpjkR7hWK6xHffRJwhyjuZcQVwC4/IqJmu0Nn+Acp32D4qOg5k/BHyn8R+TNgNz0qfB34P3B838Ci3JflVsAfoPjfI56d6Dkqfk5rvTNpYz0f5XP2iWbIyX4KfQ6h5dxnBtXp87Mc/5179uceWXkn+LyP4ocRb+c+V93saEnq8zMo4WpVwnuohHcjrxZ216EikuJ20hSUl7WtghQ8TX3cgcw5bGSR2ZIU+yR62aB6uZ16+TgSm2F3TbTQ4in3N1FV2jE8BGncRl18FIFtsLsKw44/AbZGwdaH5kO8WyjsEYTdwtoAYbrn1a8of/Xe9U8AfzPlP4T878LORsaMbhO/pCY+fKduL5h4gJrYhCY8bNDwmZsovxs5b0btofktj82C42UD5f0CeQtgZ6aDRkcTrItK+P2vdkP1fk7p9yN9EZu75MTRaWAtN/DgnnG71+w9DOm4jxq4Fw34mQF+QujO92rUcr+q5XuollchOwi7ydrxJgeCktgI18Sf64y7ubuH903M3VDTXm4SVlJ370Lk91gTa+2RhPkjzrSpjzOzTMIPKXMFMpfA7tqYHMfTxDJO3HisY9d9L2btNwl3UuIdSPwBSyoZCzqrthSTerua1O/TpN6G7GXaQQljMZGvSxC1QkUNUtQAon7MBnhUK+hwcjHPwo5nL37B1/o2SCtMsxBC/E/4xQc7H+KPHoV2QteSw+w4uJXS+pG2mh0HpEpJSu/n0J5VN25f/9NqkFMfhcoIXcugpFBJoIs49NjxsfduveMJ0JOPQnsQuo5B6RBLDF3AoT8Tt+dIR8rBU4lCuxG6kU1G6qneTvWgEjapSuiiSuhE+oPa5UdEVDqU0IHkzSq5nZJvQfIjsJuiNWzSA3Je1Fg0qNS5NBttSH2UZYOKQW82WoiJD6ZmD3wM6nVRE81o4nGmXt4c8dXbyGn2laa1r0xOg1OigdKcSHuKj1nWC7rdrY/KyNJ/PQ/6qKMGbkYDu9gQ4ydzYsXN5sRPT4ePb7jkDZBxDSVWI/EZTRORW2odmrCjJobV6lVSTVQg+bfsqok0SFJRzOIOV+e0TgrPew0qdhN1eCZif8eOGy3HiXPwbY6cMOvA0aeX7YUclFJkCSJf0E5HuCzXXbbiqKl2MHAb+FxEDRSigZdgZyXnmV4LtihhLH/KDxas1IIFLRzWbgEhhPg6nk5pSx/6sAmmsJnSbkTa6zzHakIS5/gGjhw8NcWSue0k5Ph6isxF5F80JLsCSYycypG7r17+XtPuy6AZplBkDiKParcO4GVSeU2OSuTW+eWQyGsp9BqEHmcdFnOoxzt6s7EFTqgtcBVtgSsR9g6DxdxPx4N9k7v3+sCeNcs7ToJ736DuTULiKXZdQIjxKz2R8w7U7fpk3ZYtwLuc8iYg731296cpMz7u0qjsDQxZQTiXUNzFiPsPKwkfp0lLMp5DpXMPB64YscJUHUehWQj9RKszSCcp1IRVOaNWJZNWJQN5Z/m1Fd7RxqtJGg36gZXbFkMOU6l/Kcgb0aQNx2oSaQscOfutoQmP1aSDtA0U+dlIBDlG4BOJIfXOi09HIuGnCiz8cyMk/LPIzhD4qAB2/Ir/F0FGFXSagNLYz3/Z8X5eNatvOhQloET9CJjBfpC9HkQMLxedX+Zoy2pt2aAt+7Xl7dpyhbbcpC03a8thbXlCW57RliwxkaWRL8f+D6dCpn6pIQAA

Sheet P&Lv2
B3: x
D4: A | E4: A | F4: A | G4: P | H4: P | I4: P | J4: P | K4: P | L4: P | M4: P | N4: P | O4: P
C5: Yr | D5: 1 | E5: 2 | F5: 3 | G5: 4 | H5: 5 | I5: 6 | J5: 7 | K5: 8 | L5: 9 | M5: 10 | N5: 11 | O5: 12
B6: x | C6: Growth Forecast
C7: Total People who own an EV | D7: =(1.3*10^6) -> 1300000 | E7: =(2*10^6) -> 2000000 | F7: =3.3*10 ^6 -> 3300000 | G7: =F7*(1+ModelDrivers!$E$3) -> 3465000 | H7: =G7*(1+ModelDrivers!$E$3) -> 3638250 | I7: =H7*(1+ModelDrivers!$E$3) -> 3820162.5 | J7: =I7*(1+ModelDrivers!$E$3) -> 4011170.6 | K7: =J7*(1+ModelDrivers!$E$3) -> 4211729.2 | L7: =K7*(1+ModelDrivers!$E$3) -> 4422315.6 | M7: =L7*(1+ModelDrivers!$E$3) -> 4643431.4 | N7: =M7*(1+ModelDrivers!$E$3) -> 4875603 | O7: =N7*(1+ModelDrivers!$E$3) -> 5119383.1
C8: EV Market growth | E8: =(E7/D7)-1 -> 0.53846154 | F8: =(F7/E7)-1 -> 0.65 | G8: =(G7/F7)-1 -> 0.05 | H8: =(H7/G7)-1 -> 0.05 | I8: =(I7/H7)-1 -> 0.05 | J8: =(J7/I7)-1 -> 0.05 | K8: =(K7/J7)-1 -> 0.05 | L8: =(L7/K7)-1 -> 0.05 | ... O8: =(O7/N7)-1 -> 0.05 | Q8: Ref Growth Forecast
C9: Penetration % | D9: =ModelDrivers!E4 -> 0.05 | E9: =D9 -> 0.05 | F9: =E9 -> 0.05 | G9: =F9 -> 0.05 | H9: =G9 -> 0.05 | I9: =H9 -> 0.05 | J9: =I9 -> 0.05 | K9: =J9 -> 0.05 | L9: =K9 -> 0.05 | ... O9: =N9 -> 0.05
C11: Potential Customers thru Ads | D11: =D7*D$9 -> 65000 | E11: =E7*E$9 -> 100000 | F11: =F7*F$9 -> 165000 | G11: =G7*G$9 -> 173250 | H11: =H7*H$9 -> 181912.5 | I11: =I7*I$9 -> 191008.12 | J11: =J7*J$9 -> 200558.53 | K11: =K7*K$9 -> 210586.46 | ... O11: =O7*O$9 -> 255969.16
C13: Subscription Conversion % | D13: =ModelDrivers!E5 -> 0.02 | E13: =D13 -> 0.02 | F13: =E13 -> 0.02 | G13: =F13 -> 0.02 | H13: =G13 -> 0.02 | I13: =H13 -> 0.02 | J13: =I13 -> 0.02 | K13: =J13 -> 0.02 | L13: =K13 -> 0.02 | ... O13: =N13 -> 0.02 | Q13: Ref Headcount Forecast
C15: NEW Yearly Number of Subscribers | D15: =(D13)*D11 -> 1300 | E15: =(E13)*E11 -> 2000 | F15: =(F13)*F11 -> 3300 | G15: =(G13)*G11 -> 3465 | H15: =(H13)*H11 -> 3638.25 | I15: =(I13)*I11 -> 3820.1625 | J15: =(J13)*J11 -> 4011.1706 | K15: =(K13)*K11 -> 4211.7292 | ... O15: =(O13)*O11 -> 5119.3831
C17: Total Customers | D17: =D15 -> 1300 | E17: =(E15+D17) +E107 -> 2897 | F17: =(F15+E17) +F107 -> 5577 | G17: =(G15+F17) +G107 -> 7993 | H17: =(H15+G17) +H107 -> 10361.1 | I17: =(I15+H17) +I107 -> 12747.405 | J17: =(J15+I17) +J107 -> 15109.025 | K17: =(K15+J17) +K107 -> 17588.727 | L17: =(L15+K17) +L107 -> 20192.413 | ... O17: =(O15+N17) +O107 -> 28810.94
B21: x | C21: Cohort Retention
C22: 1 | D22: =ChurnMatrix!E5 -> 0.56 | E22: =ChurnMatrix!F5 -> 0.25 | F22: =ChurnMatrix!G5 -> 0.25 | G22: =ChurnMatrix!H5 -> 0.23 | H22: =ChurnMatrix!I5 -> 0.11 | I22: =ChurnMatrix!J5 -> 0.11
C23: =C22+1 -> 2 | D23: =IF(OR(D$5>($C23+5),(D$5-$C23)<0),"",_xlfn.XLOOKUP(D$5-$C22,ModelDrivers!$G$4:$G$9,ModelDrivers!$H$4:$H$9)) | E23: =IF(OR(E$5>($C23+5),(E$5-$C23)<0),"",_xlfn.XLOOKUP(E$5-$C22,ModelDrivers!$G$4:$G$9,ModelDrivers!$H$4:$H$9)) -> 0.56 | F23: =IF(OR(F$5>($C23+5),(F$5-$C23)<0),"",_xlfn.XLOOKUP(F$5-$C22,ModelDrivers!$G$4:$G$9,ModelDrivers!$H$4:$H$9)) -> 0.25 | G23: =IF(OR(G$5>($C23+5),(G$5-$C23)<0),"",_xlfn.XLOOKUP(G$5-$C22,ModelDrivers!$G$4:$G$9,ModelDrivers!$H$4:$H$9)) -> 0.25 | H23: =IF(OR(H$5>($C23+5),(H$5-$C23)<0),"",_xlfn.XLOOKUP(H$5-$C22,ModelDrivers!$G$4:$G$9,ModelDrivers!$H$4:$H$9)) -> 0.23 | I23: =IF(OR(I$5>($C23+5),(I$5-$C23)<0),"",_xlfn.XLOOKUP(I$5-$C22,ModelDrivers!$G$4:$G$9,ModelDrivers!$H$4:$H$9)) -> 0.11 | J23: =IF(OR(J$5>($C23+5),(J$5-$C23)<0),"",_xlfn.XLOOKUP(J$5-$C22,ModelDrivers!$G$4:$G$9,ModelDrivers!$H$4:$H$9)) -> 0.11 | K23: =IF(OR(K$5>($C23+5),(K$5-$C23)<0),"",_xlfn.XLOOKUP(K$5-$C22,ModelDrivers!$G$4:$G$9,ModelDrivers!$H$4:$H$9)) | ... O23: =IF(OR(O$5>($C23+5),(O$5-$C23)<0),"",_xlfn.XLOOKUP(O$5-$C22,ModelDrivers!$G$4:$G$9,ModelDrivers!$H$4:$H$9))
C24: =C23+1 -> 3 | D24: =IF(OR(D$5>($C24+5),(D$5-$C24)<0),"",_xlfn.XLOOKUP(D$5-$C23,ModelDrivers!$G$4:$G$9,ModelDrivers!$H$4:$H$9)) | E24: =IF(OR(E$5>($C24+5),(E$5-$C24)<0),"",_xlfn.XLOOKUP(E$5-$C23,ModelDrivers!$G$4:$G$9,ModelDrivers!$H$4:$H$9)) | F24: =IF(OR(F$5>($C24+5),(F$5-$C24)<0),"",_xlfn.XLOOKUP(F$5-$C23,ModelDrivers!$G$4:$G$9,ModelDrivers!$H$4:$H$9)) -> 0.56 | G24: =IF(OR(G$5>($C24+5),(G$5-$C24)<0),"",_xlfn.XLOOKUP(G$5-$C23,ModelDrivers!$G$4:$G$9,ModelDrivers!$H$4:$H$9)) -> 0.25 | H24: =IF(OR(H$5>($C24+5),(H$5-$C24)<0),"",_xlfn.XLOOKUP(H$5-$C23,ModelDrivers!$G$4:$G$9,ModelDrivers!$H$4:$H$9)) -> 0.25 | I24: =IF(OR(I$5>($C24+5),(I$5-$C24)<0),"",_xlfn.XLOOKUP(I$5-$C23,ModelDrivers!$G$4:$G$9,ModelDrivers!$H$4:$H$9)) -> 0.23 | J24: =IF(OR(J$5>($C24+5),(J$5-$C24)<0),"",_xlfn.XLOOKUP(J$5-$C23,ModelDrivers!$G$4:$G$9,ModelDrivers!$H$4:$H$9)) -> 0.11 | K24: =IF(OR(K$5>($C24+5),(K$5-$C24)<0),"",_xlfn.XLOOKUP(K$5-$C23,ModelDrivers!$G$4:$G$9,ModelDrivers!$H$4:$H$9)) -> 0.11 | ... O24: =IF(OR(O$5>($C24+5),(O$5-$C24)<0),"",_xlfn.XLOOKUP(O$5-$C23,ModelDrivers!$G$4:$G$9,ModelDrivers!$H$4:$H$9))
C25: =C24+1 -> 4 | D25: =IF(OR(D$5>($C25+5),(D$5-$C25)<0),"",_xlfn.XLOOKUP(D$5-$C24,ModelDrivers!$G$4:$G$9,ModelDrivers!$H$4:$H$9)) | E25: =IF(OR(E$5>($C25+5),(E$5-$C25)<0),"",_xlfn.XLOOKUP(E$5-$C24,ModelDrivers!$G$4:$G$9,ModelDrivers!$H$4:$H$9)) | F25: =IF(OR(F$5>($C25+5),(F$5-$C25)<0),"",_xlfn.XLOOKUP(F$5-$C24,ModelDrivers!$G$4:$G$9,ModelDrivers!$H$4:$H$9)) | G25: =IF(OR(G$5>($C25+5),(G$5-$C25)<0),"",_xlfn.XLOOKUP(G$5-$C24,ModelDrivers!$G$4:$G$9,ModelDrivers!$H$4:$H$9)) -> 0.56 | H25: =IF(OR(H$5>($C25+5),(H$5-$C25)<0),"",_xlfn.XLOOKUP(H$5-$C24,ModelDrivers!$G$4:$G$9,ModelDrivers!$H$4:$H$9)) -> 0.25 | I25: =IF(OR(I$5>($C25+5),(I$5-$C25)<0),"",_xlfn.XLOOKUP(I$5-$C24,ModelDrivers!$G$4:$G$9,ModelDrivers!$H$4:$H$9)) -> 0.25 | J25: =IF(OR(J$5>($C25+5),(J$5-$C25)<0),"",_xlfn.XLOOKUP(J$5-$C24,ModelDrivers!$G$4:$G$9,ModelDrivers!$H$4:$H$9)) -> 0.23 | K25: =IF(OR(K$5>($C25+5),(K$5-$C25)<0),"",_xlfn.XLOOKUP(K$5-$C24,ModelDrivers!$G$4:$G$9,ModelDrivers!$H$4:$H$9)) -> 0.11 | ... O25: =IF(OR(O$5>($C25+5),(O$5-$C25)<0),"",_xlfn.XLOOKUP(O$5-$C24,ModelDrivers!$G$4:$G$9,ModelDrivers!$H$4:$H$9))
C26: =C25+1 -> 5 | D26: =IF(OR(D$5>($C26+5),(D$5-$C26)<0),"",_xlfn.XLOOKUP(D$5-$C25,ModelDrivers!$G$4:$G$9,ModelDrivers!$H$4:$H$9)) | E26: =IF(OR(E$5>($C26+5),(E$5-$C26)<0),"",_xlfn.XLOOKUP(E$5-$C25,ModelDrivers!$G$4:$G$9,ModelDrivers!$H$4:$H$9)) | F26: =IF(OR(F$5>($C26+5),(F$5-$C26)<0),"",_xlfn.XLOOKUP(F$5-$C25,ModelDrivers!$G$4:$G$9,ModelDrivers!$H$4:$H$9)) | G26: =IF(OR(G$5>($C26+5),(G$5-$C26)<0),"",_xlfn.XLOOKUP(G$5-$C25,ModelDrivers!$G$4:$G$9,ModelDrivers!$H$4:$H$9)) | H26: =IF(OR(H$5>($C26+5),(H$5-$C26)<0),"",_xlfn.XLOOKUP(H$5-$C25,ModelDrivers!$G$4:$G$9,ModelDrivers!$H$4:$H$9)) -> 0.56 | I26: =IF(OR(I$5>($C26+5),(I$5-$C26)<0),"",_xlfn.XLOOKUP(I$5-$C25,ModelDrivers!$G$4:$G$9,ModelDrivers!$H$4:$H$9)) -> 0.25 | J26: =IF(OR(J$5>($C26+5),(J$5-$C26)<0),"",_xlfn.XLOOKUP(J$5-$C25,ModelDrivers!$G$4:$G$9,ModelDrivers!$H$4:$H$9)) -> 0.25 | K26: =IF(OR(K$5>($C26+5),(K$5-$C26)<0),"",_xlfn.XLOOKUP(K$5-$C25,ModelDrivers!$G$4:$G$9,ModelDrivers!$H$4:$H$9)) -> 0.23 | ... O26: =IF(OR(O$5>($C26+5),(O$5-$C26)<0),"",_xlfn.XLOOKUP(O$5-$C25,ModelDrivers!$G$4:$G$9,ModelDrivers!$H$4:$H$9))
C27: =C26+1 -> 6 | D27: =IF(OR(D$5>($C27+5),(D$5-$C27)<0),"",_xlfn.XLOOKUP(D$5-$C26,ModelDrivers!$G$4:$G$9,ModelDrivers!$H$4:$H$9)) | E27: =IF(OR(E$5>($C27+5),(E$5-$C27)<0),"",_xlfn.XLOOKUP(E$5-$C26,ModelDrivers!$G$4:$G$9,ModelDrivers!$H$4:$H$9)) | F27: =IF(OR(F$5>($C27+5),(F$5-$C27)<0),"",_xlfn.XLOOKUP(F$5-$C26,ModelDrivers!$G$4:$G$9,ModelDrivers!$H$4:$H$9)) | G27: =IF(OR(G$5>($C27+5),(G$5-$C27)<0),"",_xlfn.XLOOKUP(G$5-$C26,ModelDrivers!$G$4:$G$9,ModelDrivers!$H$4:$H$9)) | H27: =IF(OR(H$5>($C27+5),(H$5-$C27)<0),"",_xlfn.XLOOKUP(H$5-$C26,ModelDrivers!$G$4:$G$9,ModelDrivers!$H$4:$H$9)) | I27: =IF(OR(I$5>($C27+5),(I$5-$C27)<0),"",_xlfn.XLOOKUP(I$5-$C26,ModelDrivers!$G$4:$G$9,ModelDrivers!$H$4:$H$9)) -> 0.56 | J27: =IF(OR(J$5>($C27+5),(J$5-$C27)<0),"",_xlfn.XLOOKUP(J$5-$C26,ModelDrivers!$G$4:$G$9,ModelDrivers!$H$4:$H$9)) -> 0.25 | K27: =IF(OR(K$5>($C27+5),(K$5-$C27)<0),"",_xlfn.XLOOKUP(K$5-$C26,ModelDrivers!$G$4:$G$9,ModelDrivers!$H$4:$H$9)) -> 0.25 | ... O27: =IF(OR(O$5>($C27+5),(O$5-$C27)<0),"",_xlfn.XLOOKUP(O$5-$C26,ModelDrivers!$G$4:$G$9,ModelDrivers!$H$4:$H$9))
C28: =C27+1 -> 7 | D28: =IF(OR(D$5>($C28+5),(D$5-$C28)<0),"",_xlfn.XLOOKUP(D$5-$C27,ModelDrivers!$G$4:$G$9,ModelDrivers!$H$4:$H$9)) | E28: =IF(OR(E$5>($C28+5),(E$5-$C28)<0),"",_xlfn.XLOOKUP(E$5-$C27,ModelDrivers!$G$4:$G$9,ModelDrivers!$H$4:$H$9)) | F28: =IF(OR(F$5>($C28+5),(F$5-$C28)<0),"",_xlfn.XLOOKUP(F$5-$C27,ModelDrivers!$G$4:$G$9,ModelDrivers!$H$4:$H$9)) | G28: =IF(OR(G$5>($C28+5),(G$5-$C28)<0),"",_xlfn.XLOOKUP(G$5-$C27,ModelDrivers!$G$4:$G$9,ModelDrivers!$H$4:$H$9)) | H28: =IF(OR(H$5>($C28+5),(H$5-$C28)<0),"",_xlfn.XLOOKUP(H$5-$C27,ModelDrivers!$G$4:$G$9,ModelDrivers!$H$4:$H$9)) | I28: =IF(OR(I$5>($C28+5),(I$5-$C28)<0),"",_xlfn.XLOOKUP(I$5-$C27,ModelDrivers!$G$4:$G$9,ModelDrivers!$H$4:$H$9)) | J28: =IF(OR(J$5>($C28+5),(J$5-$C28)<0),"",_xlfn.XLOOKUP(J$5-$C27,ModelDrivers!$G$4:$G$9,ModelDrivers!$H$4:$H$9)) -> 0.56 | K28: =IF(OR(K$5>($C28+5),(K$5-$C28)<0),"",_xlfn.XLOOKUP(K$5-$C27,ModelDrivers!$G$4:$G$9,ModelDrivers!$H$4:$H$9)) -> 0.25 | ... O28: =IF(OR(O$5>($C28+5),(O$5-$C28)<0),"",_xlfn.XLOOKUP(O$5-$C27,ModelDrivers!$G$4:$G$9,ModelDrivers!$H$4:$H$9)) -> 0.11
C29: =C28+1 -> 8 | D29: =IF(OR(D$5>($C29+5),(D$5-$C29)<0),"",_xlfn.XLOOKUP(D$5-$C28,ModelDrivers!$G$4:$G$9,ModelDrivers!$H$4:$H$9)) | E29: =IF(OR(E$5>($C29+5),(E$5-$C29)<0),"",_xlfn.XLOOKUP(E$5-$C28,ModelDrivers!$G$4:$G$9,ModelDrivers!$H$4:$H$9)) | F29: =IF(OR(F$5>($C29+5),(F$5-$C29)<0),"",_xlfn.XLOOKUP(F$5-$C28,ModelDrivers!$G$4:$G$9,ModelDrivers!$H$4:$H$9)) | G29: =IF(OR(G$5>($C29+5),(G$5-$C29)<0),"",_xlfn.XLOOKUP(G$5-$C28,ModelDrivers!$G$4:$G$9,ModelDrivers!$H$4:$H$9)) | H29: =IF(OR(H$5>($C29+5),(H$5-$C29)<0),"",_xlfn.XLOOKUP(H$5-$C28,ModelDrivers!$G$4:$G$9,ModelDrivers!$H$4:$H$9)) | I29: =IF(OR(I$5>($C29+5),(I$5-$C29)<0),"",_xlfn.XLOOKUP(I$5-$C28,ModelDrivers!$G$4:$G$9,ModelDrivers!$H$4:$H$9)) | J29: =IF(OR(J$5>($C29+5),(J$5-$C29)<0),"",_xlfn.XLOOKUP(J$5-$C28,ModelDrivers!$G$4:$G$9,ModelDrivers!$H$4:$H$9)) | K29: =IF(OR(K$5>($C29+5),(K$5-$C29)<0),"",_xlfn.XLOOKUP(K$5-$C28,ModelDrivers!$G$4:$G$9,ModelDrivers!$H$4:$H$9)) -> 0.56 | ... O29: =IF(OR(O$5>($C29+5),(O$5-$C29)<0),"",_xlfn.XLOOKUP(O$5-$C28,ModelDrivers!$G$4:$G$9,ModelDrivers!$H$4:$H$9)) -> 0.11
C30: =C29+1 -> 9 | D30: =IF(OR(D$5>($C30+5),(D$5-$C30)<0),"",_xlfn.XLOOKUP(D$5-$C29,ModelDrivers!$G$4:$G$9,ModelDrivers!$H$4:$H$9)) | E30: =IF(OR(E$5>($C30+5),(E$5-$C30)<0),"",_xlfn.XLOOKUP(E$5-$C29,ModelDrivers!$G$4:$G$9,ModelDrivers!$H$4:$H$9)) | F30: =IF(OR(F$5>($C30+5),(F$5-$C30)<0),"",_xlfn.XLOOKUP(F$5-$C29,ModelDrivers!$G$4:$G$9,ModelDrivers!$H$4:$H$9)) | G30: =IF(OR(G$5>($C30+5),(G$5-$C30)<0),"",_xlfn.XLOOKUP(G$5-$C29,ModelDrivers!$G$4:$G$9,ModelDrivers!$H$4:$H$9)) | H30: =IF(OR(H$5>($C30+5),(H$5-$C30)<0),"",_xlfn.XLOOKUP(H$5-$C29,ModelDrivers!$G$4:$G$9,ModelDrivers!$H$4:$H$9)) | I30: =IF(OR(I$5>($C30+5),(I$5-$C30)<0),"",_xlfn.XLOOKUP(I$5-$C29,ModelDrivers!$G$4:$G$9,ModelDrivers!$H$4:$H$9)) | J30: =IF(OR(J$5>($C30+5),(J$5-$C30)<0),"",_xlfn.XLOOKUP(J$5-$C29,ModelDrivers!$G$4:$G$9,ModelDrivers!$H$4:$H$9)) | K30: =IF(OR(K$5>($C30+5),(K$5-$C30)<0),"",_xlfn.XLOOKUP(K$5-$C29,ModelDrivers!$G$4:$G$9,ModelDrivers!$H$4:$H$9)) | ... O30: =IF(OR(O$5>($C30+5),(O$5-$C30)<0),"",_xlfn.XLOOKUP(O$5-$C29,ModelDrivers!$G$4:$G$9,ModelDrivers!$H$4:$H$9)) -> 0.23
C31: =C30+1 -> 10 | D31: =IF(OR(D$5>($C31+5),(D$5-$C31)<0),"",_xlfn.XLOOKUP(D$5-$C30,ModelDrivers!$G$4:$G$9,ModelDrivers!$H$4:$H$9)) | E31: =IF(OR(E$5>($C31+5),(E$5-$C31)<0),"",_xlfn.XLOOKUP(E$5-$C30,ModelDrivers!$G$4:$G$9,ModelDrivers!$H$4:$H$9)) | F31: =IF(OR(F$5>($C31+5),(F$5-$C31)<0),"",_xlfn.XLOOKUP(F$5-$C30,ModelDrivers!$G$4:$G$9,ModelDrivers!$H$4:$H$9)) | G31: =IF(OR(G$5>($C31+5),(G$5-$C31)<0),"",_xlfn.XLOOKUP(G$5-$C30,ModelDrivers!$G$4:$G$9,ModelDrivers!$H$4:$H$9)) | H31: =IF(OR(H$5>($C31+5),(H$5-$C31)<0),"",_xlfn.XLOOKUP(H$5-$C30,ModelDrivers!$G$4:$G$9,ModelDrivers!$H$4:$H$9)) | I31: =IF(OR(I$5>($C31+5),(I$5-$C31)<0),"",_xlfn.XLOOKUP(I$5-$C30,ModelDrivers!$G$4:$G$9,ModelDrivers!$H$4:$H$9)) | J31: =IF(OR(J$5>($C31+5),(J$5-$C31)<0),"",_xlfn.XLOOKUP(J$5-$C30,ModelDrivers!$G$4:$G$9,ModelDrivers!$H$4:$H$9)) | K31: =IF(OR(K$5>($C31+5),(K$5-$C31)<0),"",_xlfn.XLOOKUP(K$5-$C30,ModelDrivers!$G$4:$G$9,ModelDrivers!$H$4:$H$9)) | ... O31: =IF(OR(O$5>($C31+5),(O$5-$C31)<0),"",_xlfn.XLOOKUP(O$5-$C30,ModelDrivers!$G$4:$G$9,ModelDrivers!$H$4:$H$9)) -> 0.25
C32: =C31+1 -> 11 | D32: =IF(OR(D$5>($C32+5),(D$5-$C32)<0),"",_xlfn.XLOOKUP(D$5-$C31,ModelDrivers!$G$4:$G$9,ModelDrivers!$H$4:$H$9)) | E32: =IF(OR(E$5>($C32+5),(E$5-$C32)<0),"",_xlfn.XLOOKUP(E$5-$C31,ModelDrivers!$G$4:$G$9,ModelDrivers!$H$4:$H$9)) | F32: =IF(OR(F$5>($C32+5),(F$5-$C32)<0),"",_xlfn.XLOOKUP(F$5-$C31,ModelDrivers!$G$4:$G$9,ModelDrivers!$H$4:$H$9)) | G32: =IF(OR(G$5>($C32+5),(G$5-$C32)<0),"",_xlfn.XLOOKUP(G$5-$C31,ModelDrivers!$G$4:$G$9,ModelDrivers!$H$4:$H$9)) | H32: =IF(OR(H$5>($C32+5),(H$5-$C32)<0),"",_xlfn.XLOOKUP(H$5-$C31,ModelDrivers!$G$4:$G$9,ModelDrivers!$H$4:$H$9)) | I32: =IF(OR(I$5>($C32+5),(I$5-$C32)<0),"",_xlfn.XLOOKUP(I$5-$C31,ModelDrivers!$G$4:$G$9,ModelDrivers!$H$4:$H$9)) | J32: =IF(OR(J$5>($C32+5),(J$5-$C32)<0),"",_xlfn.XLOOKUP(J$5-$C31,ModelDrivers!$G$4:$G$9,ModelDrivers!$H$4:$H$9)) | K32: =IF(OR(K$5>($C32+5),(K$5-$C32)<0),"",_xlfn.XLOOKUP(K$5-$C31,ModelDrivers!$G$4:$G$9,ModelDrivers!$H$4:$H$9)) | ... O32: =IF(OR(O$5>($C32+5),(O$5-$C32)<0),"",_xlfn.XLOOKUP(O$5-$C31,ModelDrivers!$G$4:$G$9,ModelDrivers!$H$4:$H$9)) -> 0.25
C33: =C32+1 -> 12 | D33: =IF(OR(D$5>($C33+5),(D$5-$C33)<0),"",_xlfn.XLOOKUP(D$5-$C32,ModelDrivers!$G$4:$G$9,ModelDrivers!$H$4:$H$9)) | E33: =IF(OR(E$5>($C33+5),(E$5-$C33)<0),"",_xlfn.XLOOKUP(E$5-$C32,ModelDrivers!$G$4:$G$9,ModelDrivers!$H$4:$H$9)) | F33: =IF(OR(F$5>($C33+5),(F$5-$C33)<0),"",_xlfn.XLOOKUP(F$5-$C32,ModelDrivers!$G$4:$G$9,ModelDrivers!$H$4:$H$9)) | G33: =IF(OR(G$5>($C33+5),(G$5-$C33)<0),"",_xlfn.XLOOKUP(G$5-$C32,ModelDrivers!$G$4:$G$9,ModelDrivers!$H$4:$H$9)) | H33: =IF(OR(H$5>($C33+5),(H$5-$C33)<0),"",_xlfn.XLOOKUP(H$5-$C32,ModelDrivers!$G$4:$G$9,ModelDrivers!$H$4:$H$9)) | I33: =IF(OR(I$5>($C33+5),(I$5-$C33)<0),"",_xlfn.XLOOKUP(I$5-$C32,ModelDrivers!$G$4:$G$9,ModelDrivers!$H$4:$H$9)) | J33: =IF(OR(J$5>($C33+5),(J$5-$C33)<0),"",_xlfn.XLOOKUP(J$5-$C32,ModelDrivers!$G$4:$G$9,ModelDrivers!$H$4:$H$9)) | K33: =IF(OR(K$5>($C33+5),(K$5-$C33)<0),"",_xlfn.XLOOKUP(K$5-$C32,ModelDrivers!$G$4:$G$9,ModelDrivers!$H$4:$H$9)) | ... O33: =IF(OR(O$5>($C33+5),(O$5-$C33)<0),"",_xlfn.XLOOKUP(O$5-$C32,ModelDrivers!$G$4:$G$9,ModelDrivers!$H$4:$H$9)) -> 0.56
